Workbook
Name A: [1]잔업시간!#REF!
Name A: 잔업시간!#REF!

Sheet 달력
B1: 의료과 숙직근무 달력
B2: 년도 : | C2: 2026
B3: 월 : | C3: 8
B5: =DATE(C2,C3,1) -> 46235
B6: 일 | C6: 월 | D6: 화 | E6: 수 | F6: 목 | G6: 금 | H6: 토
B7: {=IFERROR("["&VLOOKUP(_xlfn.SEQUENCE(6,7,B5-WEEKDAY(B5)+1,1),공휴일!B:C,2,0)&"]","")&TEXT(_xlfn.SEQUENCE(6,7,B5-WEEKDAY(B5)+1,1),"m/d")&CHAR(10)&IFERROR(VLOOKUP(_xlfn.SEQUENCE(6,7,B5-WEEKDAY(B5)+1,1),숙직근무자!B:G,2,0),"")&IFERROR(IF(VLOOKUP(_xlfn.SEQUENCE(6,7,B5-WEEKDAY(B5)+1,1),숙직근무자!B:G,3,0)>0,"("&VLOOKUP(_xlfn.SEQUENCE(6,7,B5-WEEKDAY(B5)+1,1),숙직근무자!B:G,3,0)&")",""),"")&CHAR(10)&IFERROR(VLOOKUP(_xlfn.SEQUENCE(6,7,B5-WEEKDAY(B5)+1,1),숙직근무자!B:G,4,0),"")&IFERROR(IF(VLOOKUP(_xlfn.SEQUENCE(6,7,B5-WEEKDAY(B5)+1,1),숙직근무자!B:G,5,0)>0,"("&VLOOKUP(_xlfn.SEQUENCE(6,7,B5-WEEKDAY(B5)+1,1),숙직근무자!B:G,5,0)&")",""),"")&CHAR(10)&IFERROR(IF(VLOOKUP(_xlfn.SEQUENCE(6,7,B5-WEEKDAY(B5)+1,1),숙직근무자!B:G,6,0)>0,VLOOKUP(_xlfn.SEQUENCE(6,7,B5-WEEKDAY(B5)+1,1),숙직근무자!B:G,6,0),""),"")} -> 7/26 고석규 이승현(정찬웅) | C7: 7/27 구민아 오기희 *인사이동 | D7: 7/28 유진수 우정수 | E7: 7/29 이현숙 이원철 | F7: 7/30 신혜원 정찬웅(서진호) | G7: 7/31 유진수 서진호(정찬웅) | H7: 8/1 구민아 오기희 | J7: {=_xlfn.SEQUENCE(6,7,B5-WEEKDAY(B5)+1,1)} -> 46229 | K7: 46230 | L7: 46231 | M7: 46232 | N7: 46233 | O7: 46234 | P7: 46235
B8: 8/2 고석규 이승현 | C8: 8/3 한문영 유진수 | D8: 8/4 이현숙 이원철 | E8: 8/5 안지영 정찬웅 | F8: 8/6 송남철 서진호 | G8: 8/7 신혜원 장민우 | H8: 8/8 여철호 우정수(이승현) | J8: 46236 | K8: 46237 | L8: 46238 | M8: 46239 | N8: 46240 | O8: 46241 | P8: 46242
B9: 8/9 구민아 오기희 | C9: 8/10 고석규 이승현(우정수) | D9: 8/11 한문영 유진수 | E9: 8/12 이현숙 이원철 | F9: 8/13 안지영(송남철) 정찬웅 | G9: 8/14 송남철(안지영) 서진호 | H9: [광복절]8/15 신혜원 장민우 | J9: 46243 | K9: 46244 | L9: 46245 | M9: 46246 | N9: 46247 | O9: 46248 | P9: 46249
B10: 8/16 여철호 우정수(구민아) | C10: [대체공휴일]8/17 구민아(우정수) 오기희 | D10: 8/18 고석규 이승현(정찬웅) *을지훈련 | E10: 8/19 한문영 유진수 *을지훈련 | F10: 8/20 이현숙 이원철 *을지훈련 | G10: 8/21 안지영(송남철) 정찬웅(이승현) *을지훈련 | H10: 8/22 송남철(안지영) 서진호 | J10: 46250 | K10: 46251 | L10: 46252 | M10: 46253 | N10: 46254 | O10: 46255 | P10: 46256
B11: 8/23 신혜원 장민우(유진수) | C11: 8/24 여철호 우정수(구민아) | D11: 8/25 구민아(우정수) 오기희 | E11: 8/26 고석규 이승현 | F11: 8/27 한문영 유진수 | G11: 8/28 이현숙 이원철 | H11: 8/29 안지영 정찬웅(서진호) | J11: 46257 | K11: 46258 | L11: 46259 | M11: 46260 | N11: 46261 | O11: 46262 | P11: 46263
B12: 8/30 송남철 서진호(정찬웅) | C12: 8/31 신혜원 장민우(이승현) | D12: 9/1 여철호 우정수 | E12: 9/2 구민아 오기희 | F12: 9/3 고석규 이승현(한문영) | G12: 9/4 한문영(이승현) 유진수 | H12: 9/5 이현숙 이원철 | J12: 46264 | K12: 46265 | L12: 46266 | M12: 46267 | N12: 46268 | O12: 46269 | P12: 46270

Sheet 숙직근무자
B1: 순번1 | C1: 구민아 | D1: 고석규 | E1: 한문영 | F1: 이현숙 | G1: 안지영 | H1: 송남철 | I1: 신혜원 | J1: 여철호 | M1: 순번1 | N1: 구민아 | O1: 고석규 | P1: 한문영 | Q1: 이현숙 | R1: 안지영 | S1: 송남철 | T1: 신혜원 | U1: 여철호
B2: 순번2 | C2: 오기희 | D2: 이승현 | E2: 유진수 | F2: 이원철 | G2: 정찬웅 | H2: 서진호 | I2: 장민우 | J2: 우정수 | M2: 순번2 | N2: 오기희 | O2: 이승현 | P2: 유진수 | Q2: 이원철 | R2: 정찬웅 | S2: 서진호 | T2: 장민우 | U2: 우정수
B4: 날짜 | C4: 근무자1 | D4: 대직1 | E4: 근무자2 | F4: 대직2 | G4: 메모 | H4: 근무구분 | I4: 참고 년월 | J4: 실제근무1 | K4: 실제근무2
B5: 46224 | C5: 신혜원 | D5: 안지영 | E5: 이원철 | H5: =IF(WORKDAY(B5-1,1,공휴일!$B$4:$B$24)=B5,IF(WORKDAY(B5,1,공휴일!$B$4:$B$24)<>B5+1,"금요일","평일"),IF(WORKDAY(B5,1,공휴일!$B$4:$B$24)<>B5+1,"토요일","일요일")) -> 평일 | I5: =TEXT(B5,"yyyy-mm") -> 2026-07 | J5: =IF(D5="",C5,D5) -> 안지영 | K5: =IF(F5="",E5,F5) -> 이원철 | L5: =TEXT(B5,"aaa") -> 화 | M5: =IFERROR(VLOOKUP(B5,공휴일!B:C,2,0),"")
B6: 46225 | C6: 유진수 | E6: 정찬웅 | H6: =IF(WORKDAY(B6-1,1,공휴일!$B$4:$B$24)=B6,IF(WORKDAY(B6,1,공휴일!$B$4:$B$24)<>B6+1,"금요일","평일"),IF(WORKDAY(B6,1,공휴일!$B$4:$B$24)<>B6+1,"토요일","일요일")) -> 평일 | I6: =TEXT(B6,"yyyy-mm") -> 2026-07 | J6: =IF(D6="",C6,D6) -> 유진수 | K6: =IF(F6="",E6,F6) -> 정찬웅 | L6: =TEXT(B6,"aaa") -> 수 | M6: =IFERROR(VLOOKUP(B6,공휴일!B:C,2,0),"")
B7: 46226 | C7: 장민우 | D7: 박찬식 | E7: 서진호 | H7: =IF(WORKDAY(B7-1,1,공휴일!$B$4:$B$24)=B7,IF(WORKDAY(B7,1,공휴일!$B$4:$B$24)<>B7+1,"금요일","평일"),IF(WORKDAY(B7,1,공휴일!$B$4:$B$24)<>B7+1,"토요일","일요일")) -> 평일 | I7: =TEXT(B7,"yyyy-mm") -> 2026-07 | J7: =IF(D7="",C7,D7) -> 박찬식 | K7: =IF(F7="",E7,F7) -> 서진호 | L7: =TEXT(B7,"aaa") -> 목 | M7: =IFERROR(VLOOKUP(B7,공휴일!B:C,2,0),"") | W7: 구민아 | X7: 고석규 | Y7: 안지영 | Z7: 송남철 | AA7: 한문영 | AB7: 여철호 | AC7: 신혜원 | AD7: 이현숙
B8: 46227 | C8: 한문영 | E8: 박찬식 | F8: 장민우 | H8: =IF(WORKDAY(B8-1,1,공휴일!$B$4:$B$24)=B8,IF(WORKDAY(B8,1,공휴일!$B$4:$B$24)<>B8+1,"금요일","평일"),IF(WORKDAY(B8,1,공휴일!$B$4:$B$24)<>B8+1,"토요일","일요일")) -> 금요일 | I8: =TEXT(B8,"yyyy-mm") -> 2026-07 | J8: =IF(D8="",C8,D8) -> 한문영 | K8: =IF(F8="",E8,F8) -> 장민우 | L8: =TEXT(B8,"aaa") -> 금 | M8: =IFERROR(VLOOKUP(B8,공휴일!B:C,2,0),"")
B9: 46228 | C9: 안지영 | E9: 이승현 | F9: 우정수 | H9: =IF(WORKDAY(B9-1,1,공휴일!$B$4:$B$24)=B9,IF(WORKDAY(B9,1,공휴일!$B$4:$B$24)<>B9+1,"금요일","평일"),IF(WORKDAY(B9,1,공휴일!$B$4:$B$24)<>B9+1,"토요일","일요일")) -> 토요일 | I9: =TEXT(B9,"yyyy-mm") -> 2026-07 | J9: =IF(D9="",C9,D9) -> 안지영 | K9: =IF(F9="",E9,F9) -> 우정수 | L9: =TEXT(B9,"aaa") -> 토 | M9: =IFERROR(VLOOKUP(B9,공휴일!B:C,2,0),"") | W9: 오기희 | X9: 이승현 | Y9: 장민우 | Z9: 이원철 | AA9: 정찬웅 | AB9: 우정수 | AC9: 서진호 | AD9: 유진수
B10: 46229 | C10: 고석규 | E10: 이승현 | F10: 정찬웅 | H10: =IF(WORKDAY(B10-1,1,공휴일!$B$4:$B$24)=B10,IF(WORKDAY(B10,1,공휴일!$B$4:$B$24)<>B10+1,"금요일","평일"),IF(WORKDAY(B10,1,공휴일!$B$4:$B$24)<>B10+1,"토요일","일요일")) -> 일요일 | I10: =TEXT(B10,"yyyy-mm") -> 2026-07 | J10: =IF(D10="",C10,D10) -> 고석규 | K10: =IF(F10="",E10,F10) -> 정찬웅 | L10: =TEXT(B10,"aaa") -> 일 | M10: =IFERROR(VLOOKUP(B10,공휴일!B:C,2,0),"")
B11: 46230 | C11: 구민아 | E11: 오기희 | G11: *인사이동 | H11: =IF(WORKDAY(B11-1,1,공휴일!$B$4:$B$24)=B11,IF(WORKDAY(B11,1,공휴일!$B$4:$B$24)<>B11+1,"금요일","평일"),IF(WORKDAY(B11,1,공휴일!$B$4:$B$24)<>B11+1,"토요일","일요일")) -> 평일 | I11: =TEXT(B11,"yyyy-mm") -> 2026-07 | J11: =IF(D11="",C11,D11) -> 구민아 | K11: =IF(F11="",E11,F11) -> 오기희 | L11: =TEXT(B11,"aaa") -> 월 | M11: =IFERROR(VLOOKUP(B11,공휴일!B:C,2,0),"")
B12: 46231 | C12: 유진수 | E12: 우정수 | H12: =IF(WORKDAY(B12-1,1,공휴일!$B$4:$B$24)=B12,IF(WORKDAY(B12,1,공휴일!$B$4:$B$24)<>B12+1,"금요일","평일"),IF(WORKDAY(B12,1,공휴일!$B$4:$B$24)<>B12+1,"토요일","일요일")) -> 평일 | I12: =TEXT(B12,"yyyy-mm") -> 2026-07 | J12: =IF(D12="",C12,D12) -> 유진수 | K12: =IF(F12="",E12,F12) -> 우정수 | L12: =TEXT(B12,"aaa") -> 화 | M12: =IFERROR(VLOOKUP(B12,공휴일!B:C,2,0),"")
B13: 46232 | C13: 이현숙 | E13: 이원철 | H13: =IF(WORKDAY(B13-1,1,공휴일!$B$4:$B$24)=B13,IF(WORKDAY(B13,1,공휴일!$B$4:$B$24)<>B13+1,"금요일","평일"),IF(WORKDAY(B13,1,공휴일!$B$4:$B$24)<>B13+1,"토요일","일요일")) -> 평일 | I13: =TEXT(B13,"yyyy-mm") -> 2026-07 | J13: =IF(D13="",C13,D13) -> 이현숙 | K13: =IF(F13="",E13,F13) -> 이원철 | L13: =TEXT(B13,"aaa") -> 수 | M13: =IFERROR(VLOOKUP(B13,공휴일!B:C,2,0),"")
B14: 46233 | C14: 신혜원 | E14: 정찬웅 | F14: 서진호 | H14: =IF(WORKDAY(B14-1,1,공휴일!$B$4:$B$24)=B14,IF(WORKDAY(B14,1,공휴일!$B$4:$B$24)<>B14+1,"금요일","평일"),IF(WORKDAY(B14,1,공휴일!$B$4:$B$24)<>B14+1,"토요일","일요일")) -> 평일 | I14: =TEXT(B14,"yyyy-mm") -> 2026-07 | J14: =IF(D14="",C14,D14) -> 신혜원 | K14: =IF(F14="",E14,F14) -> 서진호 | L14: =TEXT(B14,"aaa") -> 목 | M14: =IFERROR(VLOOKUP(B14,공휴일!B:C,2,0),"")
B15: 46234 | C15: 유진수 | E15: 서진호 | F15: 정찬웅 | H15: =IF(WORKDAY(B15-1,1,공휴일!$B$4:$B$24)=B15,IF(WORKDAY(B15,1,공휴일!$B$4:$B$24)<>B15+1,"금요일","평일"),IF(WORKDAY(B15,1,공휴일!$B$4:$B$24)<>B15+1,"토요일","일요일")) -> 금요일 | I15: =TEXT(B15,"yyyy-mm") -> 2026-07 | J15: =IF(D15="",C15,D15) -> 유진수 | K15: =IF(F15="",E15,F15) -> 정찬웅 | L15: =TEXT(B15,"aaa") -> 금 | M15: =IFERROR(VLOOKUP(B15,공휴일!B:C,2,0),"")
B16: 46235 | C16: 구민아 | E16: 오기희 | H16: =IF(WORKDAY(B16-1,1,공휴일!$B$4:$B$24)=B16,IF(WORKDAY(B16,1,공휴일!$B$4:$B$24)<>B16+1,"금요일","평일"),IF(WORKDAY(B16,1,공휴일!$B$4:$B$24)<>B16+1,"토요일","일요일")) -> 토요일 | I16: =TEXT(B16,"yyyy-mm") -> 2026-08 | J16: =IF(D16="",C16,D16) -> 구민아 | K16: =IF(F16="",E16,F16) -> 오기희 | L16: =TEXT(B16,"aaa") -> 토 | M16: =IFERROR(VLOOKUP(B16,공휴일!B:C,2,0),"")
B17: 46236 | C17: 고석규 | E17: 이승현 | H17: =IF(WORKDAY(B17-1,1,공휴일!$B$4:$B$24)=B17,IF(WORKDAY(B17,1,공휴일!$B$4:$B$24)<>B17+1,"금요일","평일"),IF(WORKDAY(B17,1,공휴일!$B$4:$B$24)<>B17+1,"토요일","일요일")) -> 일요일 | I17: =TEXT(B17,"yyyy-mm") -> 2026-08 | J17: =IF(D17="",C17,D17) -> 고석규 | K17: =IF(F17="",E17,F17) -> 이승현 | L17: =TEXT(B17,"aaa") -> 일 | M17: =IFERROR(VLOOKUP(B17,공휴일!B:C,2,0),"")
B18: 46237 | C18: 한문영 | E18: 유진수 | H18: =IF(WORKDAY(B18-1,1,공휴일!$B$4:$B$24)=B18,IF(WORKDAY(B18,1,공휴일!$B$4:$B$24)<>B18+1,"금요일","평일"),IF(WORKDAY(B18,1,공휴일!$B$4:$B$24)<>B18+1,"토요일","일요일")) -> 평일 | I18: =TEXT(B18,"yyyy-mm") -> 2026-08 | J18: =IF(D18="",C18,D18) -> 한문영 | K18: =IF(F18="",E18,F18) -> 유진수 | L18: =TEXT(B18,"aaa") -> 월 | M18: =IFERROR(VLOOKUP(B18,공휴일!B:C,2,0),"")
B19: 46238 | C19: 이현숙 | E19: 이원철 | H19: =IF(WORKDAY(B19-1,1,공휴일!$B$4:$B$24)=B19,IF(WORKDAY(B19,1,공휴일!$B$4:$B$24)<>B19+1,"금요일","평일"),IF(WORKDAY(B19,1,공휴일!$B$4:$B$24)<>B19+1,"토요일","일요일")) -> 평일 | I19: =TEXT(B19,"yyyy-mm") -> 2026-08 | J19: =IF(D19="",C19,D19) -> 이현숙 | K19: =IF(F19="",E19,F19) -> 이원철 | L19: =TEXT(B19,"aaa") -> 화 | M19: =IFERROR(VLOOKUP(B19,공휴일!B:C,2,0),"")
B20: 46239 | C20: 안지영 | E20: 정찬웅 | H20: =IF(WORKDAY(B20-1,1,공휴일!$B$4:$B$24)=B20,IF(WORKDAY(B20,1,공휴일!$B$4:$B$24)<>B20+1,"금요일","평일"),IF(WORKDAY(B20,1,공휴일!$B$4:$B$24)<>B20+1,"토요일","일요일")) -> 평일 | I20: =TEXT(B20,"yyyy-mm") -> 2026-08 | J20: =IF(D20="",C20,D20) -> 안지영 | K20: =IF(F20="",E20,F20) -> 정찬웅 | L20: =TEXT(B20,"aaa") -> 수 | M20: =IFERROR(VLOOKUP(B20,공휴일!B:C,2,0),"")
B21: 46240 | C21: 송남철 | E21: 서진호 | H21: =IF(WORKDAY(B21-1,1,공휴일!$B$4:$B$24)=B21,IF(WORKDAY(B21,1,공휴일!$B$4:$B$24)<>B21+1,"금요일","평일"),IF(WORKDAY(B21,1,공휴일!$B$4:$B$24)<>B21+1,"토요일","일요일")) -> 평일 | I21: =TEXT(B21,"yyyy-mm") -> 2026-08 | J21: =IF(D21="",C21,D21) -> 송남철 | K21: =IF(F21="",E21,F21) -> 서진호 | L21: =TEXT(B21,"aaa") -> 목 | M21: =IFERROR(VLOOKUP(B21,공휴일!B:C,2,0),"")
B22: 46241 | C22: 신혜원 | E22: 장민우 | H22: =IF(WORKDAY(B22-1,1,공휴일!$B$4:$B$24)=B22,IF(WORKDAY(B22,1,공휴일!$B$4:$B$24)<>B22+1,"금요일","평일"),IF(WORKDAY(B22,1,공휴일!$B$4:$B$24)<>B22+1,"토요일","일요일")) -> 금요일 | I22: =TEXT(B22,"yyyy-mm") -> 2026-08 | J22: =IF(D22="",C22,D22) -> 신혜원 | K22: =IF(F22="",E22,F22) -> 장민우 | L22: =TEXT(B22,"aaa") -> 금 | M22: =IFERROR(VLOOKUP(B22,공휴일!B:C,2,0),"")
B23: 46242 | C23: 여철호 | E23: 우정수 | F23: 이승현 | H23: =IF(WORKDAY(B23-1,1,공휴일!$B$4:$B$24)=B23,IF(WORKDAY(B23,1,공휴일!$B$4:$B$24)<>B23+1,"금요일","평일"),IF(WORKDAY(B23,1,공휴일!$B$4:$B$24)<>B23+1,"토요일","일요일")) -> 토요일 | I23: =TEXT(B23,"yyyy-mm") -> 2026-08 | J23: =IF(D23="",C23,D23) -> 여철호 | K23: =IF(F23="",E23,F23) -> 이승현 | L23: =TEXT(B23,"aaa") -> 토 | M23: =IFERROR(VLOOKUP(B23,공휴일!B:C,2,0),"")
B24: 46243 | C24: 구민아 | E24: 오기희 | H24: =IF(WORKDAY(B24-1,1,공휴일!$B$4:$B$24)=B24,IF(WORKDAY(B24,1,공휴일!$B$4:$B$24)<>B24+1,"금요일","평일"),IF(WORKDAY(B24,1,공휴일!$B$4:$B$24)<>B24+1,"토요일","일요일")) -> 일요일 | I24: =TEXT(B24,"yyyy-mm") -> 2026-08 | J24: =IF(D24="",C24,D24) -> 구민아 | K24: =IF(F24="",E24,F24) -> 오기희 | L24: =TEXT(B24,"aaa") -> 일 | M24: =IFERROR(VLOOKUP(B24,공휴일!B:C,2,0),"")
B25: 46244 | C25: 고석규 | E25: 이승현 | F25: 우정수 | H25: =IF(WORKDAY(B25-1,1,공휴일!$B$4:$B$24)=B25,IF(WORKDAY(B25,1,공휴일!$B$4:$B$24)<>B25+1,"금요일","평일"),IF(WORKDAY(B25,1,공휴일!$B$4:$B$24)<>B25+1,"토요일","일요일")) -> 평일 | I25: =TEXT(B25,"yyyy-mm") -> 2026-08 | J25: =IF(D25="",C25,D25) -> 고석규 | K25: =IF(F25="",E25,F25) -> 우정수 | L25: =TEXT(B25,"aaa") -> 월 | M25: =IFERROR(VLOOKUP(B25,공휴일!B:C,2,0),"")
B26: 46245 | C26: 한문영 | E26: 유진수 | H26: =IF(WORKDAY(B26-1,1,공휴일!$B$4:$B$24)=B26,IF(WORKDAY(B26,1,공휴일!$B$4:$B$24)<>B26+1,"금요일","평일"),IF(WORKDAY(B26,1,공휴일!$B$4:$B$24)<>B26+1,"토요일","일요일")) -> 평일 | I26: =TEXT(B26,"yyyy-mm") -> 2026-08 | J26: =IF(D26="",C26,D26) -> 한문영 | K26: =IF(F26="",E26,F26) -> 유진수 | L26: =TEXT(B26,"aaa") -> 화 | M26: =IFERROR(VLOOKUP(B26,공휴일!B:C,2,0),"")
B27: 46246 | C27: 이현숙 | E27: 이원철 | H27: =IF(WORKDAY(B27-1,1,공휴일!$B$4:$B$24)=B27,IF(WORKDAY(B27,1,공휴일!$B$4:$B$24)<>B27+1,"금요일","평일"),IF(WORKDAY(B27,1,공휴일!$B$4:$B$24)<>B27+1,"토요일","일요일")) -> 평일 | I27: =TEXT(B27,"yyyy-mm") -> 2026-08 | J27: =IF(D27="",C27,D27) -> 이현숙 | K27: =IF(F27="",E27,F27) -> 이원철 | L27: =TEXT(B27,"aaa") -> 수 | M27: =IFERROR(VLOOKUP(B27,공휴일!B:C,2,0),"")
B28: 46247 | C28: 안지영 | D28: 송남철 | E28: 정찬웅 | H28: =IF(WORKDAY(B28-1,1,공휴일!$B$4:$B$24)=B28,IF(WORKDAY(B28,1,공휴일!$B$4:$B$24)<>B28+1,"금요일","평일"),IF(WORKDAY(B28,1,공휴일!$B$4:$B$24)<>B28+1,"토요일","일요일")) -> 평일 | I28: =TEXT(B28,"yyyy-mm") -> 2026-08 | J28: =IF(D28="",C28,D28) -> 송남철 | K28: =IF(F28="",E28,F28) -> 정찬웅 | L28: =TEXT(B28,"aaa") -> 목 | M28: =IFERROR(VLOOKUP(B28,공휴일!B:C,2,0),"")
B29: 46248 | C29: 송남철 | D29: 안지영 | E29: 서진호 | H29: =IF(WORKDAY(B29-1,1,공휴일!$B$4:$B$24)=B29,IF(WORKDAY(B29,1,공휴일!$B$4:$B$24)<>B29+1,"금요일","평일"),IF(WORKDAY(B29,1,공휴일!$B$4:$B$24)<>B29+1,"토요일","일요일")) -> 금요일 | I29: =TEXT(B29,"yyyy-mm") -> 2026-08 | J29: =IF(D29="",C29,D29) -> 안지영 | K29: =IF(F29="",E29,F29) -> 서진호 | L29: =TEXT(B29,"aaa") -> 금 | M29: =IFERROR(VLOOKUP(B29,공휴일!B:C,2,0),"")
B30: 46249 | C30: 신혜원 | E30: 장민우 | H30: =IF(WORKDAY(B30-1,1,공휴일!$B$4:$B$24)=B30,IF(WORKDAY(B30,1,공휴일!$B$4:$B$24)<>B30+1,"금요일","평일"),IF(WORKDAY(B30,1,공휴일!$B$4:$B$24)<>B30+1,"토요일","일요일")) -> 토요일 | I30: =TEXT(B30,"yyyy-mm") -> 2026-08 | J30: =IF(D30="",C30,D30) -> 신혜원 | K30: =IF(F30="",E30,F30) -> 장민우 | L30: =TEXT(B30,"aaa") -> 토 | M30: =IFERROR(VLOOKUP(B30,공휴일!B:C,2,0),"") -> 광복절
B31: 46250 | C31: 여철호 | E31: 우정수 | F31: 구민아 | H31: =IF(WORKDAY(B31-1,1,공휴일!$B$4:$B$24)=B31,IF(WORKDAY(B31,1,공휴일!$B$4:$B$24)<>B31+1,"금요일","평일"),IF(WORKDAY(B31,1,공휴일!$B$4:$B$24)<>B31+1,"토요일","일요일")) -> 토요일 | I31: =TEXT(B31,"yyyy-mm") -> 2026-08 | J31: =IF(D31="",C31,D31) -> 여철호 | K31: =IF(F31="",E31,F31) -> 구민아 | L31: =TEXT(B31,"aaa") -> 일 | M31: =IFERROR(VLOOKUP(B31,공휴일!B:C,2,0),"")
B32: 46251 | C32: 구민아 | D32: 우정수 | E32: 오기희 | H32: =IF(WORKDAY(B32-1,1,공휴일!$B$4:$B$24)=B32,IF(WORKDAY(B32,1,공휴일!$B$4:$B$24)<>B32+1,"금요일","평일"),IF(WORKDAY(B32,1,공휴일!$B$4:$B$24)<>B32+1,"토요일","일요일")) -> 일요일 | I32: =TEXT(B32,"yyyy-mm") -> 2026-08 | J32: =IF(D32="",C32,D32) -> 우정수 | K32: =IF(F32="",E32,F32) -> 오기희 | L32: =TEXT(B32,"aaa") -> 월 | M32: =IFERROR(VLOOKUP(B32,공휴일!B:C,2,0),"") -> 대체공휴일
B33: 46252 | C33: 고석규 | E33: 이승현 | F33: 정찬웅 | G33: *을지훈련 | H33: =IF(WORKDAY(B33-1,1,공휴일!$B$4:$B$24)=B33,IF(WORKDAY(B33,1,공휴일!$B$4:$B$24)<>B33+1,"금요일","평일"),IF(WORKDAY(B33,1,공휴일!$B$4:$B$24)<>B33+1,"토요일","일요일")) -> 평일 | I33: =TEXT(B33,"yyyy-mm") -> 2026-08 | J33: =IF(D33="",C33,D33) -> 고석규 | K33: =IF(F33="",E33,F33) -> 정찬웅 | L33: =TEXT(B33,"aaa") -> 화 | M33: =IFERROR(VLOOKUP(B33,공휴일!B:C,2,0),"")
B34: 46253 | C34: 한문영 | E34: 유진수 | G34: *을지훈련 | H34: =IF(WORKDAY(B34-1,1,공휴일!$B$4:$B$24)=B34,IF(WORKDAY(B34,1,공휴일!$B$4:$B$24)<>B34+1,"금요일","평일"),IF(WORKDAY(B34,1,공휴일!$B$4:$B$24)<>B34+1,"토요일","일요일")) -> 평일 | I34: =TEXT(B34,"yyyy-mm") -> 2026-08 | J34: =IF(D34="",C34,D34) -> 한문영 | K34: =IF(F34="",E34,F34) -> 유진수 | L34: =TEXT(B34,"aaa") -> 수 | M34: =IFERROR(VLOOKUP(B34,공휴일!B:C,2,0),"")
B35: 46254 | C35: 이현숙 | E35: 이원철 | G35: *을지훈련 | H35: =IF(WORKDAY(B35-1,1,공휴일!$B$4:$B$24)=B35,IF(WORKDAY(B35,1,공휴일!$B$4:$B$24)<>B35+1,"금요일","평일"),IF(WORKDAY(B35,1,공휴일!$B$4:$B$24)<>B35+1,"토요일","일요일")) -> 평일 | I35: =TEXT(B35,"yyyy-mm") -> 2026-08 | J35: =IF(D35="",C35,D35) -> 이현숙 | K35: =IF(F35="",E35,F35) -> 이원철 | L35: =TEXT(B35,"aaa") -> 목 | M35: =IFERROR(VLOOKUP(B35,공휴일!B:C,2,0),"")
B36: 46255 | C36: 안지영 | D36: 송남철 | E36: 정찬웅 | F36: 이승현 | G36: *을지훈련 | H36: =IF(WORKDAY(B36-1,1,공휴일!$B$4:$B$24)=B36,IF(WORKDAY(B36,1,공휴일!$B$4:$B$24)<>B36+1,"금요일","평일"),IF(WORKDAY(B36,1,공휴일!$B$4:$B$24)<>B36+1,"토요일","일요일")) -> 금요일 | I36: =TEXT(B36,"yyyy-mm") -> 2026-08 | J36: =IF(D36="",C36,D36) -> 송남철 | K36: =IF(F36="",E36,F36) -> 이승현 | L36: =TEXT(B36,"aaa") -> 금 | M36: =IFERROR(VLOOKUP(B36,공휴일!B:C,2,0),"")
B37: 46256 | C37: 송남철 | D37: 안지영 | E37: 서진호 | H37: =IF(WORKDAY(B37-1,1,공휴일!$B$4:$B$24)=B37,IF(WORKDAY(B37,1,공휴일!$B$4:$B$24)<>B37+1,"금요일","평일"),IF(WORKDAY(B37,1,공휴일!$B$4:$B$24)<>B37+1,"토요일","일요일")) -> 토요일 | I37: =TEXT(B37,"yyyy-mm") -> 2026-08 | J37: =IF(D37="",C37,D37) -> 안지영 | K37: =IF(F37="",E37,F37) -> 서진호 | L37: =TEXT(B37,"aaa") -> 토 | M37: =IFERROR(VLOOKUP(B37,공휴일!B:C,2,0),"")
B38: 46257 | C38: 신혜원 | E38: 장민우 | F38: 유진수 | H38: =IF(WORKDAY(B38-1,1,공휴일!$B$4:$B$24)=B38,IF(WORKDAY(B38,1,공휴일!$B$4:$B$24)<>B38+1,"금요일","평일"),IF(WORKDAY(B38,1,공휴일!$B$4:$B$24)<>B38+1,"토요일","일요일")) -> 일요일 | I38: =TEXT(B38,"yyyy-mm") -> 2026-08 | J38: =IF(D38="",C38,D38) -> 신혜원 | K38: =IF(F38="",E38,F38) -> 유진수 | L38: =TEXT(B38,"aaa") -> 일 | M38: =IFERROR(VLOOKUP(B38,공휴일!B:C,2,0),"")
B39: 46258 | C39: 여철호 | E39: 우정수 | F39: 구민아 | H39: =IF(WORKDAY(B39-1,1,공휴일!$B$4:$B$24)=B39,IF(WORKDAY(B39,1,공휴일!$B$4:$B$24)<>B39+1,"금요일","평일"),IF(WORKDAY(B39,1,공휴일!$B$4:$B$24)<>B39+1,"토요일","일요일")) -> 평일 | I39: =TEXT(B39,"yyyy-mm") -> 2026-08 | J39: =IF(D39="",C39,D39) -> 여철호 | K39: =IF(F39="",E39,F39) -> 구민아 | L39: =TEXT(B39,"aaa") -> 월 | M39: =IFERROR(VLOOKUP(B39,공휴일!B:C,2,0),"")
B40: 46259 | C40: 구민아 | D40: 우정수 | E40: 오기희 | H40: =IF(WORKDAY(B40-1,1,공휴일!$B$4:$B$24)=B40,IF(WORKDAY(B40,1,공휴일!$B$4:$B$24)<>B40+1,"금요일","평일"),IF(WORKDAY(B40,1,공휴일!$B$4:$B$24)<>B40+1,"토요일","일요일")) -> 평일 | I40: =TEXT(B40,"yyyy-mm") -> 2026-08 | J40: =IF(D40="",C40,D40) -> 우정수 | K40: =IF(F40="",E40,F40) -> 오기희 | L40: =TEXT(B40,"aaa") -> 화 | M40: =IFERROR(VLOOKUP(B40,공휴일!B:C,2,0),"")
B41: 46260 | C41: 고석규 | E41: 이승현 | H41: =IF(WORKDAY(B41-1,1,공휴일!$B$4:$B$24)=B41,IF(WORKDAY(B41,1,공휴일!$B$4:$B$24)<>B41+1,"금요일","평일"),IF(WORKDAY(B41,1,공휴일!$B$4:$B$24)<>B41+1,"토요일","일요일")) -> 평일 | I41: =TEXT(B41,"yyyy-mm") -> 2026-08 | J41: =IF(D41="",C41,D41) -> 고석규 | K41: =IF(F41="",E41,F41) -> 이승현 | L41: =TEXT(B41,"aaa") -> 수 | M41: =IFERROR(VLOOKUP(B41,공휴일!B:C,2,0),"")
...

Sheet 공휴일
B3: 날짜 | C3: 내용
B4: 46023 | C4: 신정
B5: 46069 | C5: 설날연휴
B6: 46070 | C6: 설날연휴
B7: 46071 | C7: 설날연휴
B8: 46082 | C8: 삼일절
B9: 46083 | C9: 대체공휴일
B10: 46147 | C10: 어린이날
B11: 46166 | C11: 부처님오신날
B12: 46167 | C12: 대체공휴일
B13: 46176 | C13: 제9회 전국동시지방선거
B14: 46179 | C14: 현충일
B15: 46220 | C15: 제헌절
... B65: 47112 | C65: 성탄절

Sheet 야근횟수&비번
A1: =TEXT(O1,"m")&"월 의료과 숙직 및 출근일수" -> 9월 의료과 숙직 및 출근일수 | N1: 검색 년월 : | O1: 2026-09 | P1: <-- 검색년월을 yyyy-mm형식으로 입력하면 숙직 일수 나옵니다.
A2: 연번 | B2: 성 명 | C2: 평일 | D2: 금요일 | E2: 토요일 (휴일) | F2: 일요일 (휴일) | G2: 야근 횟수 | H2: 휴일 근무 횟수 | I2: 당월 근무 일수 | J2: 비번 일수 | K2: 연가 사용 일수 | L2: 출근 일수
A3: =ROW(A3)-ROW($A$2) -> 1 | B3: 강기영 | C3: =COUNTIFS(숙직근무자!$I:$I,"*"&$O$1&"*",숙직근무자!$H:$H,"평일", 숙직근무자!$J:$J,$B3)+COUNTIFS(숙직근무자!$I:$I,"*"&$O$1&"*",숙직근무자!$H:$H,"평일", 숙직근무자!$K:$K,$B3) -> 0 | D3: =COUNTIFS(숙직근무자!$I:$I,"*"&$O$1&"*",숙직근무자!$H:$H,"금요일", 숙직근무자!$J:$J,$B3)+COUNTIFS(숙직근무자!$I:$I,"*"&$O$1&"*",숙직근무자!$H:$H,"금요일", 숙직근무자!$K:$K,$B3) -> 0 | E3: =COUNTIFS(숙직근무자!$I:$I,"*"&$O$1&"*",숙직근무자!$H:$H,"토요일", 숙직근무자!$J:$J,$B3)+COUNTIFS(숙직근무자!$I:$I,"*"&$O$1&"*",숙직근무자!$H:$H,"토요일", 숙직근무자!$K:$K,$B3) -> 0 | F3: =COUNTIFS(숙직근무자!$I:$I,"*"&$O$1&"*",숙직근무자!$H:$H,"일요일", 숙직근무자!$J:$J,$B3)+COUNTIFS(숙직근무자!$I:$I,"*"&$O$1&"*",숙직근무자!$H:$H,"일요일", 숙직근무자!$K:$K,$B3) -> 0 | G3: =SUM(C3:F3) -> 0 | H3: =SUM(E3:F3) -> 0 | J3: =C3+F3 -> 0 | L3: 부이사관
A4: =ROW(A4)-ROW($A$2) -> 2 | B4: 김주오 | C4: =COUNTIFS(숙직근무자!$I:$I,"*"&$O$1&"*",숙직근무자!$H:$H,"평일", 숙직근무자!$J:$J,$B4)+COUNTIFS(숙직근무자!$I:$I,"*"&$O$1&"*",숙직근무자!$H:$H,"평일", 숙직근무자!$K:$K,$B4) -> 0 | D4: =COUNTIFS(숙직근무자!$I:$I,"*"&$O$1&"*",숙직근무자!$H:$H,"금요일", 숙직근무자!$J:$J,$B4)+COUNTIFS(숙직근무자!$I:$I,"*"&$O$1&"*",숙직근무자!$H:$H,"금요일", 숙직근무자!$K:$K,$B4) -> 0 | E4: =COUNTIFS(숙직근무자!$I:$I,"*"&$O$1&"*",숙직근무자!$H:$H,"토요일", 숙직근무자!$J:$J,$B4)+COUNTIFS(숙직근무자!$I:$I,"*"&$O$1&"*",숙직근무자!$H:$H,"토요일", 숙직근무자!$K:$K,$B4) -> 0 | F4: =COUNTIFS(숙직근무자!$I:$I,"*"&$O$1&"*",숙직근무자!$H:$H,"일요일", 숙직근무자!$J:$J,$B4)+COUNTIFS(숙직근무자!$I:$I,"*"&$O$1&"*",숙직근무자!$H:$H,"일요일", 숙직근무자!$K:$K,$B4) -> 0 | G4: =SUM(C4:F4) -> 0 | H4: =SUM(E4:F4) -> 0 | J4: =C4+F4 -> 0 | L4: 과학기술서기관
A5: =ROW(A5)-ROW($A$2) -> 3 | B5: 정해인 | C5: =COUNTIFS(숙직근무자!$I:$I,"*"&$O$1&"*",숙직근무자!$H:$H,"평일", 숙직근무자!$J:$J,$B5)+COUNTIFS(숙직근무자!$I:$I,"*"&$O$1&"*",숙직근무자!$H:$H,"평일", 숙직근무자!$K:$K,$B5) -> 0 | D5: =COUNTIFS(숙직근무자!$I:$I,"*"&$O$1&"*",숙직근무자!$H:$H,"금요일", 숙직근무자!$J:$J,$B5)+COUNTIFS(숙직근무자!$I:$I,"*"&$O$1&"*",숙직근무자!$H:$H,"금요일", 숙직근무자!$K:$K,$B5) -> 0 | E5: =COUNTIFS(숙직근무자!$I:$I,"*"&$O$1&"*",숙직근무자!$H:$H,"토요일", 숙직근무자!$J:$J,$B5)+COUNTIFS(숙직근무자!$I:$I,"*"&$O$1&"*",숙직근무자!$H:$H,"토요일", 숙직근무자!$K:$K,$B5) -> 0 | F5: =COUNTIFS(숙직근무자!$I:$I,"*"&$O$1&"*",숙직근무자!$H:$H,"일요일", 숙직근무자!$J:$J,$B5)+COUNTIFS(숙직근무자!$I:$I,"*"&$O$1&"*",숙직근무자!$H:$H,"일요일", 숙직근무자!$K:$K,$B5) -> 0 | G5: 0 | H5: 0 | J5: 0
A6: =ROW(A6)-ROW($A$2) -> 4 | B6: 정병기 | C6: =COUNTIFS(숙직근무자!$I:$I,"*"&$O$1&"*",숙직근무자!$H:$H,"평일", 숙직근무자!$J:$J,$B6)+COUNTIFS(숙직근무자!$I:$I,"*"&$O$1&"*",숙직근무자!$H:$H,"평일", 숙직근무자!$K:$K,$B6) -> 0 | D6: =COUNTIFS(숙직근무자!$I:$I,"*"&$O$1&"*",숙직근무자!$H:$H,"금요일", 숙직근무자!$J:$J,$B6)+COUNTIFS(숙직근무자!$I:$I,"*"&$O$1&"*",숙직근무자!$H:$H,"금요일", 숙직근무자!$K:$K,$B6) -> 0 | E6: =COUNTIFS(숙직근무자!$I:$I,"*"&$O$1&"*",숙직근무자!$H:$H,"토요일", 숙직근무자!$J:$J,$B6)+COUNTIFS(숙직근무자!$I:$I,"*"&$O$1&"*",숙직근무자!$H:$H,"토요일", 숙직근무자!$K:$K,$B6) -> 0 | F6: =COUNTIFS(숙직근무자!$I:$I,"*"&$O$1&"*",숙직근무자!$H:$H,"일요일", 숙직근무자!$J:$J,$B6)+COUNTIFS(숙직근무자!$I:$I,"*"&$O$1&"*",숙직근무자!$H:$H,"일요일", 숙직근무자!$K:$K,$B6) -> 0 | G6: =SUM(C6:F6) -> 0 | H6: =SUM(E6:F6) -> 0 | J6: 0 | S6: .
A7: =ROW(A7)-ROW($A$2) -> 5 | B7: 윤인성 | C7: =COUNTIFS(숙직근무자!$I:$I,"*"&$O$1&"*",숙직근무자!$H:$H,"평일", 숙직근무자!$J:$J,$B7)+COUNTIFS(숙직근무자!$I:$I,"*"&$O$1&"*",숙직근무자!$H:$H,"평일", 숙직근무자!$K:$K,$B7) -> 0 | D7: =COUNTIFS(숙직근무자!$I:$I,"*"&$O$1&"*",숙직근무자!$H:$H,"금요일", 숙직근무자!$J:$J,$B7)+COUNTIFS(숙직근무자!$I:$I,"*"&$O$1&"*",숙직근무자!$H:$H,"금요일", 숙직근무자!$K:$K,$B7) -> 0 | E7: =COUNTIFS(숙직근무자!$I:$I,"*"&$O$1&"*",숙직근무자!$H:$H,"토요일", 숙직근무자!$J:$J,$B7)+COUNTIFS(숙직근무자!$I:$I,"*"&$O$1&"*",숙직근무자!$H:$H,"토요일", 숙직근무자!$K:$K,$B7) -> 0 | F7: =COUNTIFS(숙직근무자!$I:$I,"*"&$O$1&"*",숙직근무자!$H:$H,"일요일", 숙직근무자!$J:$J,$B7)+COUNTIFS(숙직근무자!$I:$I,"*"&$O$1&"*",숙직근무자!$H:$H,"일요일", 숙직근무자!$K:$K,$B7) -> 0 | G7: =SUM(C7:F7) -> 0 | H7: =SUM(E7:F7) -> 0 | J7: =C7+F7 -> 0
A8: =ROW(A8)-ROW($A$2) -> 6 | B8: 고석규 | C8: =COUNTIFS(숙직근무자!$I:$I,"*"&$O$1&"*",숙직근무자!$H:$H,"평일", 숙직근무자!$J:$J,$B8)+COUNTIFS(숙직근무자!$I:$I,"*"&$O$1&"*",숙직근무자!$H:$H,"평일", 숙직근무자!$K:$K,$B8) -> 1 | D8: =COUNTIFS(숙직근무자!$I:$I,"*"&$O$1&"*",숙직근무자!$H:$H,"금요일", 숙직근무자!$J:$J,$B8)+COUNTIFS(숙직근무자!$I:$I,"*"&$O$1&"*",숙직근무자!$H:$H,"금요일", 숙직근무자!$K:$K,$B8) -> 1 | E8: =COUNTIFS(숙직근무자!$I:$I,"*"&$O$1&"*",숙직근무자!$H:$H,"토요일", 숙직근무자!$J:$J,$B8)+COUNTIFS(숙직근무자!$I:$I,"*"&$O$1&"*",숙직근무자!$H:$H,"토요일", 숙직근무자!$K:$K,$B8) -> 1 | F8: =COUNTIFS(숙직근무자!$I:$I,"*"&$O$1&"*",숙직근무자!$H:$H,"일요일", 숙직근무자!$J:$J,$B8)+COUNTIFS(숙직근무자!$I:$I,"*"&$O$1&"*",숙직근무자!$H:$H,"일요일", 숙직근무자!$K:$K,$B8) -> 1 | G8: =SUM(C8:F8) -> 4 | H8: =SUM(E8:F8) -> 2 | J8: =C8+F8 -> 2 | L8: 현업
A9: =ROW(A9)-ROW($A$2) -> 7 | B9: 여철호 | C9: =COUNTIFS(숙직근무자!$I:$I,"*"&$O$1&"*",숙직근무자!$H:$H,"평일", 숙직근무자!$J:$J,$B9)+COUNTIFS(숙직근무자!$I:$I,"*"&$O$1&"*",숙직근무자!$H:$H,"평일", 숙직근무자!$K:$K,$B9) -> 3 | D9: =COUNTIFS(숙직근무자!$I:$I,"*"&$O$1&"*",숙직근무자!$H:$H,"금요일", 숙직근무자!$J:$J,$B9)+COUNTIFS(숙직근무자!$I:$I,"*"&$O$1&"*",숙직근무자!$H:$H,"금요일", 숙직근무자!$K:$K,$B9) -> 0 | E9: =COUNTIFS(숙직근무자!$I:$I,"*"&$O$1&"*",숙직근무자!$H:$H,"토요일", 숙직근무자!$J:$J,$B9)+COUNTIFS(숙직근무자!$I:$I,"*"&$O$1&"*",숙직근무자!$H:$H,"토요일", 숙직근무자!$K:$K,$B9) -> 1 | F9: =COUNTIFS(숙직근무자!$I:$I,"*"&$O$1&"*",숙직근무자!$H:$H,"일요일", 숙직근무자!$J:$J,$B9)+COUNTIFS(숙직근무자!$I:$I,"*"&$O$1&"*",숙직근무자!$H:$H,"일요일", 숙직근무자!$K:$K,$B9) -> 0 | G9: =SUM(C9:F9) -> 4 | H9: =SUM(E9:F9) -> 1 | J9: =C9+F9 -> 3 | L9: 현업
A10: =ROW(A10)-ROW($A$2) -> 8 | B10: 안지영 | C10: =COUNTIFS(숙직근무자!$I:$I,"*"&$O$1&"*",숙직근무자!$H:$H,"평일", 숙직근무자!$J:$J,$B10)+COUNTIFS(숙직근무자!$I:$I,"*"&$O$1&"*",숙직근무자!$H:$H,"평일", 숙직근무자!$K:$K,$B10) -> 2 | D10: =COUNTIFS(숙직근무자!$I:$I,"*"&$O$1&"*",숙직근무자!$H:$H,"금요일", 숙직근무자!$J:$J,$B10)+COUNTIFS(숙직근무자!$I:$I,"*"&$O$1&"*",숙직근무자!$H:$H,"금요일", 숙직근무자!$K:$K,$B10) -> 1 | E10: =COUNTIFS(숙직근무자!$I:$I,"*"&$O$1&"*",숙직근무자!$H:$H,"토요일", 숙직근무자!$J:$J,$B10)+COUNTIFS(숙직근무자!$I:$I,"*"&$O$1&"*",숙직근무자!$H:$H,"토요일", 숙직근무자!$K:$K,$B10) -> 0 | F10: =COUNTIFS(숙직근무자!$I:$I,"*"&$O$1&"*",숙직근무자!$H:$H,"일요일", 숙직근무자!$J:$J,$B10)+COUNTIFS(숙직근무자!$I:$I,"*"&$O$1&"*",숙직근무자!$H:$H,"일요일", 숙직근무자!$K:$K,$B10) -> 1 | G10: =SUM(C10:F10) -> 4 | H10: =SUM(E10:F10) -> 1 | J10: =C10+F10 -> 3 | L10: 현업
A11: =ROW(A11)-ROW($A$2) -> 9 | B11: 이현숙 | C11: =COUNTIFS(숙직근무자!$I:$I,"*"&$O$1&"*",숙직근무자!$H:$H,"평일", 숙직근무자!$J:$J,$B11)+COUNTIFS(숙직근무자!$I:$I,"*"&$O$1&"*",숙직근무자!$H:$H,"평일", 숙직근무자!$K:$K,$B11) -> 2 | D11: =COUNTIFS(숙직근무자!$I:$I,"*"&$O$1&"*",숙직근무자!$H:$H,"금요일", 숙직근무자!$J:$J,$B11)+COUNTIFS(숙직근무자!$I:$I,"*"&$O$1&"*",숙직근무자!$H:$H,"금요일", 숙직근무자!$K:$K,$B11) -> 0 | E11: =COUNTIFS(숙직근무자!$I:$I,"*"&$O$1&"*",숙직근무자!$H:$H,"토요일", 숙직근무자!$J:$J,$B11)+COUNTIFS(숙직근무자!$I:$I,"*"&$O$1&"*",숙직근무자!$H:$H,"토요일", 숙직근무자!$K:$K,$B11) -> 1 | F11: =COUNTIFS(숙직근무자!$I:$I,"*"&$O$1&"*",숙직근무자!$H:$H,"일요일", 숙직근무자!$J:$J,$B11)+COUNTIFS(숙직근무자!$I:$I,"*"&$O$1&"*",숙직근무자!$H:$H,"일요일", 숙직근무자!$K:$K,$B11) -> 1 | G11: =SUM(C11:F11) -> 4 | H11: =SUM(E11:F11) -> 2 | J11: =C11+F11 -> 3 | L11: 현업
A12: =ROW(A12)-ROW($A$2) -> 10 | B12: 유진수 | C12: =COUNTIFS(숙직근무자!$I:$I,"*"&$O$1&"*",숙직근무자!$H:$H,"평일", 숙직근무자!$J:$J,$B12)+COUNTIFS(숙직근무자!$I:$I,"*"&$O$1&"*",숙직근무자!$H:$H,"평일", 숙직근무자!$K:$K,$B12) -> 2 | D12: =COUNTIFS(숙직근무자!$I:$I,"*"&$O$1&"*",숙직근무자!$H:$H,"금요일", 숙직근무자!$J:$J,$B12)+COUNTIFS(숙직근무자!$I:$I,"*"&$O$1&"*",숙직근무자!$H:$H,"금요일", 숙직근무자!$K:$K,$B12) -> 1 | E12: =COUNTIFS(숙직근무자!$I:$I,"*"&$O$1&"*",숙직근무자!$H:$H,"토요일", 숙직근무자!$J:$J,$B12)+COUNTIFS(숙직근무자!$I:$I,"*"&$O$1&"*",숙직근무자!$H:$H,"토요일", 숙직근무자!$K:$K,$B12) -> 1 | F12: =COUNTIFS(숙직근무자!$I:$I,"*"&$O$1&"*",숙직근무자!$H:$H,"일요일", 숙직근무자!$J:$J,$B12)+COUNTIFS(숙직근무자!$I:$I,"*"&$O$1&"*",숙직근무자!$H:$H,"일요일", 숙직근무자!$K:$K,$B12) -> 1 | G12: =SUM(C12:F12) -> 5 | H12: =SUM(E12:F12) -> 2 | J12: =C12+F12 -> 3 | L12: 현업
A13: =ROW(A13)-ROW($A$2) -> 11 | B13: 장민우 | C13: =COUNTIFS(숙직근무자!$I:$I,"*"&$O$1&"*",숙직근무자!$H:$H,"평일", 숙직근무자!$J:$J,$B13)+COUNTIFS(숙직근무자!$I:$I,"*"&$O$1&"*",숙직근무자!$H:$H,"평일", 숙직근무자!$K:$K,$B13) -> 1 | D13: =COUNTIFS(숙직근무자!$I:$I,"*"&$O$1&"*",숙직근무자!$H:$H,"금요일", 숙직근무자!$J:$J,$B13)+COUNTIFS(숙직근무자!$I:$I,"*"&$O$1&"*",숙직근무자!$H:$H,"금요일", 숙직근무자!$K:$K,$B13) -> 0 | E13: =COUNTIFS(숙직근무자!$I:$I,"*"&$O$1&"*",숙직근무자!$H:$H,"토요일", 숙직근무자!$J:$J,$B13)+COUNTIFS(숙직근무자!$I:$I,"*"&$O$1&"*",숙직근무자!$H:$H,"토요일", 숙직근무자!$K:$K,$B13) -> 0 | F13: =COUNTIFS(숙직근무자!$I:$I,"*"&$O$1&"*",숙직근무자!$H:$H,"일요일", 숙직근무자!$J:$J,$B13)+COUNTIFS(숙직근무자!$I:$I,"*"&$O$1&"*",숙직근무자!$H:$H,"일요일", 숙직근무자!$K:$K,$B13) -> 0 | G13: =SUM(C13:F13) -> 1 | H13: =SUM(E13:F13) -> 0 | J13: =C13+F13 -> 1 | L13: 현업
A14: =ROW(A14)-ROW($A$2) -> 12 | B14: 구민아 | C14: =COUNTIFS(숙직근무자!$I:$I,"*"&$O$1&"*",숙직근무자!$H:$H,"평일", 숙직근무자!$J:$J,$B14)+COUNTIFS(숙직근무자!$I:$I,"*"&$O$1&"*",숙직근무자!$H:$H,"평일", 숙직근무자!$K:$K,$B14) -> 2 | D14: =COUNTIFS(숙직근무자!$I:$I,"*"&$O$1&"*",숙직근무자!$H:$H,"금요일", 숙직근무자!$J:$J,$B14)+COUNTIFS(숙직근무자!$I:$I,"*"&$O$1&"*",숙직근무자!$H:$H,"금요일", 숙직근무자!$K:$K,$B14) -> 1 | E14: =COUNTIFS(숙직근무자!$I:$I,"*"&$O$1&"*",숙직근무자!$H:$H,"토요일", 숙직근무자!$J:$J,$B14)+COUNTIFS(숙직근무자!$I:$I,"*"&$O$1&"*",숙직근무자!$H:$H,"토요일", 숙직근무자!$K:$K,$B14) -> 1 | F14: =COUNTIFS(숙직근무자!$I:$I,"*"&$O$1&"*",숙직근무자!$H:$H,"일요일", 숙직근무자!$J:$J,$B14)+COUNTIFS(숙직근무자!$I:$I,"*"&$O$1&"*",숙직근무자!$H:$H,"일요일", 숙직근무자!$K:$K,$B14) -> 0 | G14: =SUM(C14:F14) -> 4 | H14: =SUM(E14:F14) -> 1 | J14: =C14+F14 -> 2 | L14: 현업
A15: =ROW(A15)-ROW($A$2) -> 13 | B15: 한문영 | C15: =COUNTIFS(숙직근무자!$I:$I,"*"&$O$1&"*",숙직근무자!$H:$H,"평일", 숙직근무자!$J:$J,$B15)+COUNTIFS(숙직근무자!$I:$I,"*"&$O$1&"*",숙직근무자!$H:$H,"평일", 숙직근무자!$K:$K,$B15) -> 2 | D15: =COUNTIFS(숙직근무자!$I:$I,"*"&$O$1&"*",숙직근무자!$H:$H,"금요일", 숙직근무자!$J:$J,$B15)+COUNTIFS(숙직근무자!$I:$I,"*"&$O$1&"*",숙직근무자!$H:$H,"금요일", 숙직근무자!$K:$K,$B15) -> 0 | E15: =COUNTIFS(숙직근무자!$I:$I,"*"&$O$1&"*",숙직근무자!$H:$H,"토요일", 숙직근무자!$J:$J,$B15)+COUNTIFS(숙직근무자!$I:$I,"*"&$O$1&"*",숙직근무자!$H:$H,"토요일", 숙직근무자!$K:$K,$B15) -> 1 | F15: =COUNTIFS(숙직근무자!$I:$I,"*"&$O$1&"*",숙직근무자!$H:$H,"일요일", 숙직근무자!$J:$J,$B15)+COUNTIFS(숙직근무자!$I:$I,"*"&$O$1&"*",숙직근무자!$H:$H,"일요일", 숙직근무자!$K:$K,$B15) -> 1 | G15: =SUM(C15:F15) -> 4 | H15: =SUM(E15:F15) -> 2 | J15: =C15+F15 -> 3 | L15: 현업
A16: =ROW(A16)-ROW($A$2) -> 14 | B16: 신혜원 | C16: =COUNTIFS(숙직근무자!$I:$I,"*"&$O$1&"*",숙직근무자!$H:$H,"평일", 숙직근무자!$J:$J,$B16)+COUNTIFS(숙직근무자!$I:$I,"*"&$O$1&"*",숙직근무자!$H:$H,"평일", 숙직근무자!$K:$K,$B16) -> 2 | D16: =COUNTIFS(숙직근무자!$I:$I,"*"&$O$1&"*",숙직근무자!$H:$H,"금요일", 숙직근무자!$J:$J,$B16)+COUNTIFS(숙직근무자!$I:$I,"*"&$O$1&"*",숙직근무자!$H:$H,"금요일", 숙직근무자!$K:$K,$B16) -> 0 | E16: =COUNTIFS(숙직근무자!$I:$I,"*"&$O$1&"*",숙직근무자!$H:$H,"토요일", 숙직근무자!$J:$J,$B16)+COUNTIFS(숙직근무자!$I:$I,"*"&$O$1&"*",숙직근무자!$H:$H,"토요일", 숙직근무자!$K:$K,$B16) -> 1 | F16: =COUNTIFS(숙직근무자!$I:$I,"*"&$O$1&"*",숙직근무자!$H:$H,"일요일", 숙직근무자!$J:$J,$B16)+COUNTIFS(숙직근무자!$I:$I,"*"&$O$1&"*",숙직근무자!$H:$H,"일요일", 숙직근무자!$K:$K,$B16) -> 0 | G16: =SUM(C16:F16) -> 3 | H16: =SUM(E16:F16) -> 1 | J16: =C16+F16 -> 2 | L16: 현업
A17: =ROW(A17)-ROW($A$2) -> 15 | B17: 최상욱 | C17: =COUNTIFS(숙직근무자!$I:$I,"*"&$O$1&"*",숙직근무자!$H:$H,"평일", 숙직근무자!$J:$J,$B17)+COUNTIFS(숙직근무자!$I:$I,"*"&$O$1&"*",숙직근무자!$H:$H,"평일", 숙직근무자!$K:$K,$B17) -> 0 | D17: =COUNTIFS(숙직근무자!$I:$I,"*"&$O$1&"*",숙직근무자!$H:$H,"금요일", 숙직근무자!$J:$J,$B17)+COUNTIFS(숙직근무자!$I:$I,"*"&$O$1&"*",숙직근무자!$H:$H,"금요일", 숙직근무자!$K:$K,$B17) -> 0 | E17: =COUNTIFS(숙직근무자!$I:$I,"*"&$O$1&"*",숙직근무자!$H:$H,"토요일", 숙직근무자!$J:$J,$B17)+COUNTIFS(숙직근무자!$I:$I,"*"&$O$1&"*",숙직근무자!$H:$H,"토요일", 숙직근무자!$K:$K,$B17) -> 0 | F17: =COUNTIFS(숙직근무자!$I:$I,"*"&$O$1&"*",숙직근무자!$H:$H,"일요일", 숙직근무자!$J:$J,$B17)+COUNTIFS(숙직근무자!$I:$I,"*"&$O$1&"*",숙직근무자!$H:$H,"일요일", 숙직근무자!$K:$K,$B17) -> 0 | G17: =SUM(C17:F17) -> 0 | H17: =SUM(E17:F17) -> 0 | J17: =C17+F17 -> 0 | L17: 현업
A18: =ROW(A18)-ROW($A$2) -> 16 | B18: 정찬웅 | C18: =COUNTIFS(숙직근무자!$I:$I,"*"&$O$1&"*",숙직근무자!$H:$H,"평일", 숙직근무자!$J:$J,$B18)+COUNTIFS(숙직근무자!$I:$I,"*"&$O$1&"*",숙직근무자!$H:$H,"평일", 숙직근무자!$K:$K,$B18) -> 3 | D18: =COUNTIFS(숙직근무자!$I:$I,"*"&$O$1&"*",숙직근무자!$H:$H,"금요일", 숙직근무자!$J:$J,$B18)+COUNTIFS(숙직근무자!$I:$I,"*"&$O$1&"*",숙직근무자!$H:$H,"금요일", 숙직근무자!$K:$K,$B18) -> 0 | E18: =COUNTIFS(숙직근무자!$I:$I,"*"&$O$1&"*",숙직근무자!$H:$H,"토요일", 숙직근무자!$J:$J,$B18)+COUNTIFS(숙직근무자!$I:$I,"*"&$O$1&"*",숙직근무자!$H:$H,"토요일", 숙직근무자!$K:$K,$B18) -> 1 | F18: =COUNTIFS(숙직근무자!$I:$I,"*"&$O$1&"*",숙직근무자!$H:$H,"일요일", 숙직근무자!$J:$J,$B18)+COUNTIFS(숙직근무자!$I:$I,"*"&$O$1&"*",숙직근무자!$H:$H,"일요일", 숙직근무자!$K:$K,$B18) -> 1 | G18: =SUM(C18:F18) -> 5 | H18: =SUM(E18:F18) -> 2 | J18: =C18+F18 -> 4 | L18: 현업
A19: =ROW(A19)-ROW($A$2) -> 17 | B19: 서진호 | C19: =COUNTIFS(숙직근무자!$I:$I,"*"&$O$1&"*",숙직근무자!$H:$H,"평일", 숙직근무자!$J:$J,$B19)+COUNTIFS(숙직근무자!$I:$I,"*"&$O$1&"*",숙직근무자!$H:$H,"평일", 숙직근무자!$K:$K,$B19) -> 2 | D19: =COUNTIFS(숙직근무자!$I:$I,"*"&$O$1&"*",숙직근무자!$H:$H,"금요일", 숙직근무자!$J:$J,$B19)+COUNTIFS(숙직근무자!$I:$I,"*"&$O$1&"*",숙직근무자!$H:$H,"금요일", 숙직근무자!$K:$K,$B19) -> 0 | E19: =COUNTIFS(숙직근무자!$I:$I,"*"&$O$1&"*",숙직근무자!$H:$H,"토요일", 숙직근무자!$J:$J,$B19)+COUNTIFS(숙직근무자!$I:$I,"*"&$O$1&"*",숙직근무자!$H:$H,"토요일", 숙직근무자!$K:$K,$B19) -> 1 | F19: =COUNTIFS(숙직근무자!$I:$I,"*"&$O$1&"*",숙직근무자!$H:$H,"일요일", 숙직근무자!$J:$J,$B19)+COUNTIFS(숙직근무자!$I:$I,"*"&$O$1&"*",숙직근무자!$H:$H,"일요일", 숙직근무자!$K:$K,$B19) -> 0 | G19: =SUM(C19:F19) -> 3 | H19: =SUM(E19:F19) -> 1 | J19: =C19+F19 -> 2 | L19: 현업
... A24: =ROW(A24)-ROW($A$2) -> 22 | B24: 송남철 | C24: =COUNTIFS(숙직근무자!$I:$I,"*"&$O$1&"*",숙직근무자!$H:$H,"평일", 숙직근무자!$J:$J,$B24)+COUNTIFS(숙직근무자!$I:$I,"*"&$O$1&"*",숙직근무자!$H:$H,"평일", 숙직근무자!$K:$K,$B24) -> 3 | D24: =COUNTIFS(숙직근무자!$I:$I,"*"&$O$1&"*",숙직근무자!$H:$H,"금요일", 숙직근무자!$J:$J,$B24)+COUNTIFS(숙직근무자!$I:$I,"*"&$O$1&"*",숙직근무자!$H:$H,"금요일", 숙직근무자!$K:$K,$B24) -> 0 | E24: =COUNTIFS(숙직근무자!$I:$I,"*"&$O$1&"*",숙직근무자!$H:$H,"토요일", 숙직근무자!$J:$J,$B24)+COUNTIFS(숙직근무자!$I:$I,"*"&$O$1&"*",숙직근무자!$H:$H,"토요일", 숙직근무자!$K:$K,$B24) -> 0 | F24: =COUNTIFS(숙직근무자!$I:$I,"*"&$O$1&"*",숙직근무자!$H:$H,"일요일", 숙직근무자!$J:$J,$B24)+COUNTIFS(숙직근무자!$I:$I,"*"&$O$1&"*",숙직근무자!$H:$H,"일요일", 숙직근무자!$K:$K,$B24) -> 0 | G24: =SUM(C24:F24) -> 3 | H24: =SUM(E24:F24) -> 0 | J24: =C24+F24 -> 3 | L24: 현업
A25: 총계 | C25: =SUM(C3:C24,D3:D24) -> 40 | E25: =SUM(E3:E24,F3:F24) -> 20 | G25: =SUM(G3:G24) -> 60 | H25: =SUM(H3:H24) -> 20 | J25: =SUM(J3:J24) -> 40 | K25: =SUM(K6:K23) -> 0

Sheet 잔업시간
A1: 연번 | B1: 부별 | C1: 직급 | D1: 성명 | E1: =TEXT('야근횟수&비번'!O1,"mm")&"월 시간외 근무수당" -> 09월 시간외 근무수당 | L1: 휴일 근무 횟수 | M1: 출근일수 | N1: 비 고 | O1: 숙직 횟수
E2: 일대:정액 (점심수당) | F2: 잔업 (e사람) | G2: 일근자:지원근무 야근자:복무시간 | H2: 실제 총 근무시간 | I2: 복무규정 근무시간 | J2: 시간 외 근무시간 | K2: 총야근 | O2: 평일 숙직 | P2: 금요일 숙직 | Q2: 토요일 숙직 | R2: 일요일 숙직
A3: =ROW(A3)-ROW($A$2) -> 1 | B3: 의료 | C3: 부이사관 | D3: 강기영 | E3: =COUNTIFS(중식!$B:$B,D3)+COUNTIFS(중식!$C:$C,D3) -> 0 | G3: =SUM(O3*7+P3*15+Q3*15+R3*7) -> 0 | H3: =SUM(E3:G3) -> 0 | J3: =IF((H3-I3)<0,0,(H3-I3)) -> 0 | K3: =VLOOKUP($D3,'야근횟수&비번'!$B$3:$L$24,6,0) -> 0 | L3: =VLOOKUP($D3,'야근횟수&비번'!$B$3:$L$24,7,0) -> 0 | M3: =VLOOKUP($D3,'야근횟수&비번'!$B$3:$L$24,11,0) -> 부이사관 | O3: =VLOOKUP($D3,'야근횟수&비번'!$B$3:$L$24,2,0) -> 0 | P3: =VLOOKUP($D3,'야근횟수&비번'!$B$3:$L$24,3,0) -> 0 | Q3: =VLOOKUP($D3,'야근횟수&비번'!$B$3:$L$24,4,0) -> 0 | R3: =VLOOKUP($D3,'야근횟수&비번'!$B$3:$L$24,5,0) -> 0
A4: =ROW(A4)-ROW($A$2) -> 2 | B4: 의료 | C4: 과학기술서기관 | D4: 김주오 | E4: =COUNTIFS(중식!$B:$B,D4)+COUNTIFS(중식!$C:$C,D4) -> 0 | G4: =SUM(O4*7+P4*15+Q4*15+R4*7) -> 0 | H4: =SUM(E4:G4) -> 0 | J4: =IF((H4-I4)<0,0,(H4-I4)) -> 0 | K4: =VLOOKUP($D4,'야근횟수&비번'!$B$3:$L$24,6,0) -> 0 | L4: =VLOOKUP($D4,'야근횟수&비번'!$B$3:$L$24,7,0) -> 0 | M4: =VLOOKUP($D4,'야근횟수&비번'!$B$3:$L$24,11,0) -> 과학기술서기관 | O4: =VLOOKUP($D4,'야근횟수&비번'!$B$3:$L$24,2,0) -> 0 | P4: =VLOOKUP($D4,'야근횟수&비번'!$B$3:$L$24,3,0) -> 0 | Q4: =VLOOKUP($D4,'야근횟수&비번'!$B$3:$L$24,4,0) -> 0 | R4: =VLOOKUP($D4,'야근횟수&비번'!$B$3:$L$24,5,0) -> 0
A5: =ROW(A5)-ROW($A$2) -> 3 | B5: 의료 | C5: 의무사무관 | D5: 정해인 | E5: =COUNTIFS(중식!$B:$B,D5)+COUNTIFS(중식!$C:$C,D5) -> 0 | G5: =SUM(O5*7+P5*15+Q5*15+R5*7) -> 0 | H5: =SUM(E5:G5) -> 0 | J5: =IF((H5-I5)<0,0,(H5-I5)) -> 0 | K5: =VLOOKUP($D5,'야근횟수&비번'!$B$3:$L$24,6,0) -> 0 | L5: =VLOOKUP($D5,'야근횟수&비번'!$B$3:$L$24,7,0) -> 0 | M5: =VLOOKUP($D5,'야근횟수&비번'!$B$3:$L$24,11,0) -> 0 | O5: =VLOOKUP($D5,'야근횟수&비번'!$B$3:$L$24,2,0) -> 0 | P5: =VLOOKUP($D5,'야근횟수&비번'!$B$3:$L$24,3,0) -> 0 | Q5: =VLOOKUP($D5,'야근횟수&비번'!$B$3:$L$24,4,0) -> 0 | R5: =VLOOKUP($D5,'야근횟수&비번'!$B$3:$L$24,5,0) -> 0
A6: =ROW(A6)-ROW($A$2) -> 4 | B6: 의료 | C6: 의무사무관 | D6: 정병기 | E6: =COUNTIFS(중식!$B:$B,D6)+COUNTIFS(중식!$C:$C,D6) -> 0 | G6: =SUM(O6*7+P6*15+Q6*15+R6*7) -> 0 | H6: =SUM(E6:G6) -> 0 | J6: =IF((H6-I6)<0,0,(H6-I6)) -> 0 | K6: =VLOOKUP($D6,'야근횟수&비번'!$B$3:$L$24,6,0) -> 0 | L6: =VLOOKUP($D6,'야근횟수&비번'!$B$3:$L$24,7,0) -> 0 | M6: =VLOOKUP($D6,'야근횟수&비번'!$B$3:$L$24,11,0) -> 0 | O6: =VLOOKUP($D6,'야근횟수&비번'!$B$3:$L$24,2,0) -> 0 | P6: =VLOOKUP($D6,'야근횟수&비번'!$B$3:$L$24,3,0) -> 0 | Q6: =VLOOKUP($D6,'야근횟수&비번'!$B$3:$L$24,4,0) -> 0 | R6: =VLOOKUP($D6,'야근횟수&비번'!$B$3:$L$24,5,0) -> 0
A7: =ROW(A7)-ROW($A$2) -> 5 | B7: 의료 | C7: 약무사무관 | D7: 윤인성 | E7: =COUNTIFS(중식!$B:$B,D7)+COUNTIFS(중식!$C:$C,D7) -> 0 | G7: =SUM(O7*7+P7*15+Q7*15+R7*7) -> 0 | H7: =SUM(E7:G7) -> 0 | J7: =IF((H7-I7)<0,0,(H7-I7)) -> 0 | K7: =VLOOKUP($D7,'야근횟수&비번'!$B$3:$L$24,6,0) -> 0 | L7: =VLOOKUP($D7,'야근횟수&비번'!$B$3:$L$24,7,0) -> 0 | M7: =VLOOKUP($D7,'야근횟수&비번'!$B$3:$L$24,11,0) -> 0 | O7: =VLOOKUP($D7,'야근횟수&비번'!$B$3:$L$24,2,0) -> 0 | P7: =VLOOKUP($D7,'야근횟수&비번'!$B$3:$L$24,3,0) -> 0 | Q7: =VLOOKUP($D7,'야근횟수&비번'!$B$3:$L$24,4,0) -> 0 | R7: =VLOOKUP($D7,'야근횟수&비번'!$B$3:$L$24,5,0) -> 0
A8: =ROW(A8)-ROW($A$2) -> 6 | B8: 의료 | C8: 6급 | D8: 고석규 | E8: =COUNTIFS(중식!$B:$B,D8)+COUNTIFS(중식!$C:$C,D8) -> 0 | G8: =SUM(O8*7+P8*15+Q8*15+R8*7) -> 44 | H8: =SUM(E8:G8) -> 44 | J8: =IF((H8-I8)<0,0,(H8-I8)) -> 44 | K8: =VLOOKUP($D8,'야근횟수&비번'!$B$3:$L$24,6,0) -> 4 | L8: =VLOOKUP($D8,'야근횟수&비번'!$B$3:$L$24,7,0) -> 2 | M8: =VLOOKUP($D8,'야근횟수&비번'!$B$3:$L$24,11,0) -> 현업 | O8: =VLOOKUP($D8,'야근횟수&비번'!$B$3:$L$24,2,0) -> 1 | P8: =VLOOKUP($D8,'야근횟수&비번'!$B$3:$L$24,3,0) -> 1 | Q8: =VLOOKUP($D8,'야근횟수&비번'!$B$3:$L$24,4,0) -> 1 | R8: =VLOOKUP($D8,'야근횟수&비번'!$B$3:$L$24,5,0) -> 1
A9: =ROW(A9)-ROW($A$2) -> 7 | B9: 의료 | C9: 6급 | D9: 여철호 | E9: =COUNTIFS(중식!$B:$B,D9)+COUNTIFS(중식!$C:$C,D9) -> 0 | G9: =SUM(O9*7+P9*15+Q9*15+R9*7) -> 36 | H9: =SUM(E9:G9) -> 36 | J9: =IF((H9-I9)<0,0,(H9-I9)) -> 36 | K9: =VLOOKUP($D9,'야근횟수&비번'!$B$3:$L$24,6,0) -> 4 | L9: =VLOOKUP($D9,'야근횟수&비번'!$B$3:$L$24,7,0) -> 1 | M9: =VLOOKUP($D9,'야근횟수&비번'!$B$3:$L$24,11,0) -> 현업 | O9: =VLOOKUP($D9,'야근횟수&비번'!$B$3:$L$24,2,0) -> 3 | P9: =VLOOKUP($D9,'야근횟수&비번'!$B$3:$L$24,3,0) -> 0 | Q9: =VLOOKUP($D9,'야근횟수&비번'!$B$3:$L$24,4,0) -> 1 | R9: =VLOOKUP($D9,'야근횟수&비번'!$B$3:$L$24,5,0) -> 0
A10: =ROW(A10)-ROW($A$2) -> 8 | B10: 의료 | C10: 간호주사 | D10: 안지영 | E10: =COUNTIFS(중식!$B:$B,D10)+COUNTIFS(중식!$C:$C,D10) -> 0 | G10: =SUM(O10*7+P10*15+Q10*15+R10*7) -> 36 | H10: =SUM(E10:G10) -> 36 | J10: =IF((H10-I10)<0,0,(H10-I10)) -> 36 | K10: =VLOOKUP($D10,'야근횟수&비번'!$B$3:$L$24,6,0) -> 4 | L10: =VLOOKUP($D10,'야근횟수&비번'!$B$3:$L$24,7,0) -> 1 | M10: =VLOOKUP($D10,'야근횟수&비번'!$B$3:$L$24,11,0) -> 현업 | O10: =VLOOKUP($D10,'야근횟수&비번'!$B$3:$L$24,2,0) -> 2 | P10: =VLOOKUP($D10,'야근횟수&비번'!$B$3:$L$24,3,0) -> 1 | Q10: =VLOOKUP($D10,'야근횟수&비번'!$B$3:$L$24,4,0) -> 0 | R10: =VLOOKUP($D10,'야근횟수&비번'!$B$3:$L$24,5,0) -> 1
A11: =ROW(A11)-ROW($A$2) -> 9 | B11: 의료 | C11: 간호주사 | D11: 이현숙 | E11: =COUNTIFS(중식!$B:$B,D11)+COUNTIFS(중식!$C:$C,D11) -> 0 | G11: =SUM(O11*7+P11*15+Q11*15+R11*7) -> 36 | H11: =SUM(E11:G11) -> 36 | J11: =IF((H11-I11)<0,0,(H11-I11)) -> 36 | K11: =VLOOKUP($D11,'야근횟수&비번'!$B$3:$L$24,6,0) -> 4 | L11: =VLOOKUP($D11,'야근횟수&비번'!$B$3:$L$24,7,0) -> 2 | M11: =VLOOKUP($D11,'야근횟수&비번'!$B$3:$L$24,11,0) -> 현업 | O11: =VLOOKUP($D11,'야근횟수&비번'!$B$3:$L$24,2,0) -> 2 | P11: =VLOOKUP($D11,'야근횟수&비번'!$B$3:$L$24,3,0) -> 0 | Q11: =VLOOKUP($D11,'야근횟수&비번'!$B$3:$L$24,4,0) -> 1 | R11: =VLOOKUP($D11,'야근횟수&비번'!$B$3:$L$24,5,0) -> 1
A12: =ROW(A12)-ROW($A$2) -> 10 | B12: 의료 | C12: 의료기술주사 | D12: 유진수 | E12: =COUNTIFS(중식!$B:$B,D12)+COUNTIFS(중식!$C:$C,D12) -> 0 | G12: =SUM(O12*7+P12*15+Q12*15+R12*7) -> 51 | H12: =SUM(E12:G12) -> 51 | J12: =IF((H12-I12)<0,0,(H12-I12)) -> 51 | K12: =VLOOKUP($D12,'야근횟수&비번'!$B$3:$L$24,6,0) -> 5 | L12: =VLOOKUP($D12,'야근횟수&비번'!$B$3:$L$24,7,0) -> 2 | M12: =VLOOKUP($D12,'야근횟수&비번'!$B$3:$L$24,11,0) -> 현업 | O12: =VLOOKUP($D12,'야근횟수&비번'!$B$3:$L$24,2,0) -> 2 | P12: =VLOOKUP($D12,'야근횟수&비번'!$B$3:$L$24,3,0) -> 1 | Q12: =VLOOKUP($D12,'야근횟수&비번'!$B$3:$L$24,4,0) -> 1 | R12: =VLOOKUP($D12,'야근횟수&비번'!$B$3:$L$24,5,0) -> 1
A13: =ROW(A13)-ROW($A$2) -> 11 | B13: 의료 | C13: 7급 | D13: 장민우 | E13: 0 | G13: =SUM(O13*7+P13*15+Q13*15+R13*7) -> 7 | H13: =SUM(E13:G13) -> 7 | J13: =IF((H13-I13)<0,0,(H13-I13)) -> 7 | K13: =VLOOKUP($D13,'야근횟수&비번'!$B$3:$L$24,6,0) -> 1 | L13: =VLOOKUP($D13,'야근횟수&비번'!$B$3:$L$24,7,0) -> 0 | M13: =VLOOKUP($D13,'야근횟수&비번'!$B$3:$L$24,11,0) -> 현업 | O13: =VLOOKUP($D13,'야근횟수&비번'!$B$3:$L$24,2,0) -> 1 | P13: =VLOOKUP($D13,'야근횟수&비번'!$B$3:$L$24,3,0) -> 0 | Q13: =VLOOKUP($D13,'야근횟수&비번'!$B$3:$L$24,4,0) -> 0 | R13: =VLOOKUP($D13,'야근횟수&비번'!$B$3:$L$24,5,0) -> 0
A14: =ROW(A14)-ROW($A$2) -> 12 | B14: 의료 | C14: 7급 | D14: 송남철 | E14: =COUNTIFS(중식!$B:$B,D14)+COUNTIFS(중식!$C:$C,D14) -> 0 | G14: =SUM(O14*7+P14*15+Q14*15+R14*7) -> 21 | H14: =SUM(E14:G14) -> 21 | J14: =IF((H14-I14)<0,0,(H14-I14)) -> 21 | K14: =VLOOKUP($D14,'야근횟수&비번'!$B$3:$L$24,6,0) -> 3 | L14: =VLOOKUP($D14,'야근횟수&비번'!$B$3:$L$24,7,0) -> 0 | M14: =VLOOKUP($D14,'야근횟수&비번'!$B$3:$L$24,11,0) -> 현업 | O14: =VLOOKUP($D14,'야근횟수&비번'!$B$3:$L$24,2,0) -> 3 | P14: =VLOOKUP($D14,'야근횟수&비번'!$B$3:$L$24,3,0) -> 0 | Q14: =VLOOKUP($D14,'야근횟수&비번'!$B$3:$L$24,4,0) -> 0 | R14: =VLOOKUP($D14,'야근횟수&비번'!$B$3:$L$24,5,0) -> 0
A15: =ROW(A15)-ROW($A$2) -> 13 | B15: 의료 | C15: 간호주사보 | D15: 구민아 | E15: =COUNTIFS(중식!$B:$B,D15)+COUNTIFS(중식!$C:$C,D15) -> 0 | G15: =SUM(O15*7+P15*15+Q15*15+R15*7) -> 44 | H15: =SUM(E15:G15) -> 44 | J15: =IF((H15-I15)<0,0,(H15-I15)) -> 44 | K15: =VLOOKUP($D15,'야근횟수&비번'!$B$3:$L$24,6,0) -> 4 | L15: =VLOOKUP($D15,'야근횟수&비번'!$B$3:$L$24,7,0) -> 1 | M15: =VLOOKUP($D15,'야근횟수&비번'!$B$3:$L$24,11,0) -> 현업 | O15: =VLOOKUP($D15,'야근횟수&비번'!$B$3:$L$24,2,0) -> 2 | P15: =VLOOKUP($D15,'야근횟수&비번'!$B$3:$L$24,3,0) -> 1 | Q15: =VLOOKUP($D15,'야근횟수&비번'!$B$3:$L$24,4,0) -> 1 | R15: =VLOOKUP($D15,'야근횟수&비번'!$B$3:$L$24,5,0) -> 0
A16: =ROW(A16)-ROW($A$2) -> 14 | B16: 의료 | C16: 간호주사보 | D16: 한문영 | E16: =COUNTIFS(중식!$B:$B,D16)+COUNTIFS(중식!$C:$C,D16) -> 0 | G16: =SUM(O16*7+P16*15+Q16*15+R16*7) -> 36 | H16: =SUM(E16:G16) -> 36 | J16: =IF((H16-I16)<0,0,(H16-I16)) -> 36 | K16: =VLOOKUP($D16,'야근횟수&비번'!$B$3:$L$24,6,0) -> 4 | L16: =VLOOKUP($D16,'야근횟수&비번'!$B$3:$L$24,7,0) -> 2 | M16: =VLOOKUP($D16,'야근횟수&비번'!$B$3:$L$24,11,0) -> 현업 | O16: =VLOOKUP($D16,'야근횟수&비번'!$B$3:$L$24,2,0) -> 2 | P16: =VLOOKUP($D16,'야근횟수&비번'!$B$3:$L$24,3,0) -> 0 | Q16: =VLOOKUP($D16,'야근횟수&비번'!$B$3:$L$24,4,0) -> 1 | R16: =VLOOKUP($D16,'야근횟수&비번'!$B$3:$L$24,5,0) -> 1
A17: =ROW(A17)-ROW($A$2) -> 15 | B17: 의료 | C17: 간호주사보 | D17: 신혜원 | E17: =COUNTIFS(중식!$B:$B,D17)+COUNTIFS(중식!$C:$C,D17) -> 0 | G17: =SUM(O17*7+P17*15+Q17*15+R17*7) -> 29 | H17: =SUM(E17:G17) -> 29 | J17: =IF((H17-I17)<0,0,(H17-I17)) -> 29 | K17: =VLOOKUP($D17,'야근횟수&비번'!$B$3:$L$24,6,0) -> 3 | L17: =VLOOKUP($D17,'야근횟수&비번'!$B$3:$L$24,7,0) -> 1 | M17: =VLOOKUP($D17,'야근횟수&비번'!$B$3:$L$24,11,0) -> 현업 | O17: =VLOOKUP($D17,'야근횟수&비번'!$B$3:$L$24,2,0) -> 2 | P17: =VLOOKUP($D17,'야근횟수&비번'!$B$3:$L$24,3,0) -> 0 | Q17: =VLOOKUP($D17,'야근횟수&비번'!$B$3:$L$24,4,0) -> 1 | R17: =VLOOKUP($D17,'야근횟수&비번'!$B$3:$L$24,5,0) -> 0
A18: =ROW(A18)-ROW($A$2) -> 16 | B18: 의료 | C18: 간호주사보 | D18: 최상욱 | E18: =COUNTIFS(중식!$B:$B,D18)+COUNTIFS(중식!$C:$C,D18) -> 0 | G18: =SUM(O18*7+P18*15+Q18*15+R18*7) -> 0 | H18: =SUM(E18:G18) -> 0 | J18: =IF((H18-I18)<0,0,(H18-I18)) -> 0 | K18: =VLOOKUP($D18,'야근횟수&비번'!$B$3:$L$24,6,0) -> 0 | L18: =VLOOKUP($D18,'야근횟수&비번'!$B$3:$L$24,7,0) -> 0 | M18: =VLOOKUP($D18,'야근횟수&비번'!$B$3:$L$24,11,0) -> 현업 | O18: =VLOOKUP($D18,'야근횟수&비번'!$B$3:$L$24,2,0) -> 0 | P18: =VLOOKUP($D18,'야근횟수&비번'!$B$3:$L$24,3,0) -> 0 | Q18: =VLOOKUP($D18,'야근횟수&비번'!$B$3:$L$24,4,0) -> 0 | R18: =VLOOKUP($D18,'야근횟수&비번'!$B$3:$L$24,5,0) -> 0
A19: =ROW(A19)-ROW($A$2) -> 17 | B19: 의료 | C19: 7급 | D19: 정찬웅 | E19: =COUNTIFS(중식!$B:$B,D19)+COUNTIFS(중식!$C:$C,D19) -> 0 | G19: =SUM(O19*7+P19*15+Q19*15+R19*7) -> 43 | H19: =SUM(E19:G19) -> 43 | J19: =IF((H19-I19)<0,0,(H19-I19)) -> 43 | K19: =VLOOKUP($D19,'야근횟수&비번'!$B$3:$L$24,6,0) -> 5 | L19: =VLOOKUP($D19,'야근횟수&비번'!$B$3:$L$24,7,0) -> 2 | M19: =VLOOKUP($D19,'야근횟수&비번'!$B$3:$L$24,11,0) -> 현업 | O19: =VLOOKUP($D19,'야근횟수&비번'!$B$3:$L$24,2,0) -> 3 | P19: =VLOOKUP($D19,'야근횟수&비번'!$B$3:$L$24,3,0) -> 0 | Q19: =VLOOKUP($D19,'야근횟수&비번'!$B$3:$L$24,4,0) -> 1 | R19: =VLOOKUP($D19,'야근횟수&비번'!$B$3:$L$24,5,0) -> 1
A20: =ROW(A20)-ROW($A$2) -> 18 | B20: 의료 | C20: 7급 | D20: 서진호 | E20: =COUNTIFS(중식!$B:$B,D20)+COUNTIFS(중식!$C:$C,D20) -> 0 | G20: =SUM(O20*7+P20*15+Q20*15+R20*7) -> 29 | H20: =SUM(E20:G20) -> 29 | J20: =IF((H20-I20)<0,0,(H20-I20)) -> 29 | K20: =VLOOKUP($D20,'야근횟수&비번'!$B$3:$L$24,6,0) -> 3 | L20: =VLOOKUP($D20,'야근횟수&비번'!$B$3:$L$24,7,0) -> 1 | M20: =VLOOKUP($D20,'야근횟수&비번'!$B$3:$L$24,11,0) -> 현업 | O20: =VLOOKUP($D20,'야근횟수&비번'!$B$3:$L$24,2,0) -> 2 | P20: =VLOOKUP($D20,'야근횟수&비번'!$B$3:$L$24,3,0) -> 0 | Q20: =VLOOKUP($D20,'야근횟수&비번'!$B$3:$L$24,4,0) -> 1 | R20: =VLOOKUP($D20,'야근횟수&비번'!$B$3:$L$24,5,0) -> 0
A21: =ROW(A21)-ROW($A$2) -> 19 | B21: 의료 | C21: 간호서기 | D21: 오기희 | E21: =COUNTIFS(중식!$B:$B,D21)+COUNTIFS(중식!$C:$C,D21) -> 0 | G21: =SUM(O21*7+P21*15+Q21*15+R21*7) -> 44 | H21: =SUM(E21:G21) -> 44 | J21: =IF((H21-I21)<0,0,(H21-I21)) -> 44 | K21: =VLOOKUP($D21,'야근횟수&비번'!$B$3:$L$24,6,0) -> 4 | L21: =VLOOKUP($D21,'야근횟수&비번'!$B$3:$L$24,7,0) -> 1 | M21: =VLOOKUP($D21,'야근횟수&비번'!$B$3:$L$24,11,0) -> 현업 | O21: =VLOOKUP($D21,'야근횟수&비번'!$B$3:$L$24,2,0) -> 2 | P21: =VLOOKUP($D21,'야근횟수&비번'!$B$3:$L$24,3,0) -> 1 | Q21: =VLOOKUP($D21,'야근횟수&비번'!$B$3:$L$24,4,0) -> 1 | R21: =VLOOKUP($D21,'야근횟수&비번'!$B$3:$L$24,5,0) -> 0
A22: =ROW(A22)-ROW($A$2) -> 20 | B22: 의료 | C22: 8급 | D22: 우정수 | E22: =COUNTIFS(중식!$B:$B,D22)+COUNTIFS(중식!$C:$C,D22) -> 0 | G22: =SUM(O22*7+P22*15+Q22*15+R22*7) -> 36 | H22: =SUM(E22:G22) -> 36 | J22: =IF((H22-I22)<0,0,(H22-I22)) -> 36 | K22: =VLOOKUP($D22,'야근횟수&비번'!$B$3:$L$24,6,0) -> 4 | L22: =VLOOKUP($D22,'야근횟수&비번'!$B$3:$L$24,7,0) -> 1 | M22: =VLOOKUP($D22,'야근횟수&비번'!$B$3:$L$24,11,0) -> 현업 | O22: =VLOOKUP($D22,'야근횟수&비번'!$B$3:$L$24,2,0) -> 3 | P22: =VLOOKUP($D22,'야근횟수&비번'!$B$3:$L$24,3,0) -> 0 | Q22: =VLOOKUP($D22,'야근횟수&비번'!$B$3:$L$24,4,0) -> 1 | R22: =VLOOKUP($D22,'야근횟수&비번'!$B$3:$L$24,5,0) -> 0
A23: =ROW(A23)-ROW($A$2) -> 21 | B23: 의료 | C23: 8급 | D23: 이원철 | E23: =COUNTIFS(중식!$B:$B,D23)+COUNTIFS(중식!$C:$C,D23) -> 0 | G23: =SUM(O23*7+P23*15+Q23*15+R23*7) -> 36 | H23: =SUM(E23:G23) -> 36 | J23: =IF((H23-I23)<0,0,(H23-I23)) -> 36 | K23: =VLOOKUP($D23,'야근횟수&비번'!$B$3:$L$24,6,0) -> 4 | L23: =VLOOKUP($D23,'야근횟수&비번'!$B$3:$L$24,7,0) -> 2 | M23: =VLOOKUP($D23,'야근횟수&비번'!$B$3:$L$24,11,0) -> 현업 | O23: =VLOOKUP($D23,'야근횟수&비번'!$B$3:$L$24,2,0) -> 2 | P23: =VLOOKUP($D23,'야근횟수&비번'!$B$3:$L$24,3,0) -> 0 | Q23: =VLOOKUP($D23,'야근횟수&비번'!$B$3:$L$24,4,0) -> 1 | R23: =VLOOKUP($D23,'야근횟수&비번'!$B$3:$L$24,5,0) -> 1
A24: =ROW(A24)-ROW($A$2) -> 22 | B24: 의료 | C24: 8급 | D24: 이승현 | E24: =COUNTIFS(중식!$B:$B,D24)+COUNTIFS(중식!$C:$C,D24) -> 0 | G24: =SUM(O24*7+P24*15+Q24*15+R24*7) -> 52 | H24: =SUM(E24:G24) -> 52 | J24: =IF((H24-I24)<0,0,(H24-I24)) -> 52 | K24: =VLOOKUP($D24,'야근횟수&비번'!$B$3:$L$24,6,0) -> 4 | L24: =VLOOKUP($D24,'야근횟수&비번'!$B$3:$L$24,7,0) -> 1 | M24: =VLOOKUP($D24,'야근횟수&비번'!$B$3:$L$24,11,0) -> 현업 | O24: =VLOOKUP($D24,'야근횟수&비번'!$B$3:$L$24,2,0) -> 0 | P24: =VLOOKUP($D24,'야근횟수&비번'!$B$3:$L$24,3,0) -> 3 | Q24: =VLOOKUP($D24,'야근횟수&비번'!$B$3:$L$24,4,0) -> 0 | R24: =VLOOKUP($D24,'야근횟수&비번'!$B$3:$L$24,5,0) -> 1
A25: 22 | B25: 의료 | G25: =SUM(O25*7+P25*15+Q25*15+R25*7) -> 21 | H25: =SUM(E25:G25) -> 21 | J25: =IF((H25-I25)<0,0,(H25-I25)) -> 21 | K25: ='야근횟수&비번'!G24 -> 3 | L25: ='야근횟수&비번'!H24 -> 0 | M25: ='야근횟수&비번'!L24 -> 현업 | O25: ='야근횟수&비번'!C24 -> 3 | P25: ='야근횟수&비번'!D24 -> 0 | Q25: ='야근횟수&비번'!E24 -> 0 | R25: ='야근횟수&비번'!F24 -> 0

Sheet 의료과 개인별 초과근무내역
A1: =TEXT('야근횟수&비번'!O1,"yyyy년 mm월"&" 의료과 개인별 초과근무내역") -> 2026년 09월 의료과 개인별 초과근무내역
A2: 수신 : 총무과장 | I2: 발신 : 의료과장
A3: 연 번 | B3: 부 별 | C3: 직 급 | D3: 성 명 | E3: 지급할 시간(일)수 | H3: 출 근 근무일수 | I3: 비고
E4: 총 시간 외 근무시간 | F4: 야간근무 수당(일) | G4: 휴일근무 수당(일)
A6: =ROW(A6)-ROW($A$5) -> 1 | B6: 의료 | C6: 부이사관 | D6: 강기영 | E6: =VLOOKUP($D6,잔업시간!$D$3:'잔업시간'!$M$24,7,0) -> 0 | F6: =VLOOKUP($D6,잔업시간!$D$3:'잔업시간'!$M$24,8,0) -> 0 | G6: =VLOOKUP($D6,잔업시간!$D$3:'잔업시간'!$M$24,9,0) -> 0 | H6: =VLOOKUP($D6,잔업시간!$D$3:'잔업시간'!$M$24,10,0) -> 부이사관
A7: =ROW(A7)-ROW($A$5) -> 2 | B7: 의료 | C7: 과학기술서기관 | D7: 김주오 | E7: =VLOOKUP($D7,잔업시간!$D$3:'잔업시간'!$M$24,7,0) -> 0 | F7: =VLOOKUP($D7,잔업시간!$D$3:'잔업시간'!$M$24,8,0) -> 0 | G7: =VLOOKUP($D7,잔업시간!$D$3:'잔업시간'!$M$24,9,0) -> 0 | H7: =VLOOKUP($D7,잔업시간!$D$3:'잔업시간'!$M$24,10,0) -> 과학기술서기관
A8: =ROW(A8)-ROW($A$5) -> 3 | B8: 의료 | C8: 의무사무관 | D8: 정해인 | E8: =VLOOKUP($D8,잔업시간!$D$3:'잔업시간'!$M$24,7,0) -> 0 | F8: =VLOOKUP($D8,잔업시간!$D$3:'잔업시간'!$M$24,8,0) -> 0 | G8: =VLOOKUP($D8,잔업시간!$D$3:'잔업시간'!$M$24,9,0) -> 0 | H8: =VLOOKUP($D8,잔업시간!$D$3:'잔업시간'!$M$24,10,0) -> 0
A9: =ROW(A9)-ROW($A$5) -> 4 | B9: 의료 | C9: 의무사무관 | D9: 정병기 | E9: =VLOOKUP($D9,잔업시간!$D$3:'잔업시간'!$M$24,7,0) -> 0 | F9: =VLOOKUP($D9,잔업시간!$D$3:'잔업시간'!$M$24,8,0) -> 0 | G9: =VLOOKUP($D9,잔업시간!$D$3:'잔업시간'!$M$24,9,0) -> 0 | H9: =VLOOKUP($D9,잔업시간!$D$3:'잔업시간'!$M$24,10,0) -> 0
A10: =ROW(A10)-ROW($A$5) -> 5 | B10: 의료 | C10: 약무사무관 | D10: 윤인성 | E10: =VLOOKUP($D10,잔업시간!$D$3:'잔업시간'!$M$24,7,0) -> 0 | F10: =VLOOKUP($D10,잔업시간!$D$3:'잔업시간'!$M$24,8,0) -> 0 | G10: =VLOOKUP($D10,잔업시간!$D$3:'잔업시간'!$M$24,9,0) -> 0 | H10: =VLOOKUP($D10,잔업시간!$D$3:'잔업시간'!$M$24,10,0) -> 0
A11: =ROW(A11)-ROW($A$5) -> 6 | B11: 의료 | C11: 6급 | D11: 고석규 | E11: =VLOOKUP($D11,잔업시간!$D$3:'잔업시간'!$M$24,7,0) -> 44 | F11: =VLOOKUP($D11,잔업시간!$D$3:'잔업시간'!$M$24,8,0) -> 4 | G11: =VLOOKUP($D11,잔업시간!$D$3:'잔업시간'!$M$24,9,0) -> 2 | H11: =VLOOKUP($D11,잔업시간!$D$3:'잔업시간'!$M$24,10,0) -> 현업
A12: =ROW(A12)-ROW($A$5) -> 7 | B12: 의료 | C12: 6급 | D12: 여철호 | E12: =VLOOKUP($D12,잔업시간!$D$3:'잔업시간'!$M$24,7,0) -> 36 | F12: =VLOOKUP($D12,잔업시간!$D$3:'잔업시간'!$M$24,8,0) -> 4 | G12: =VLOOKUP($D12,잔업시간!$D$3:'잔업시간'!$M$24,9,0) -> 1 | H12: =VLOOKUP($D12,잔업시간!$D$3:'잔업시간'!$M$24,10,0) -> 현업
A13: =ROW(A13)-ROW($A$5) -> 8 | B13: 의료 | C13: 간호주사 | D13: 안지영 | E13: =VLOOKUP($D13,잔업시간!$D$3:'잔업시간'!$M$24,7,0) -> 36 | F13: =VLOOKUP($D13,잔업시간!$D$3:'잔업시간'!$M$24,8,0) -> 4 | G13: =VLOOKUP($D13,잔업시간!$D$3:'잔업시간'!$M$24,9,0) -> 1 | H13: =VLOOKUP($D13,잔업시간!$D$3:'잔업시간'!$M$24,10,0) -> 현업
A14: =ROW(A14)-ROW($A$5) -> 9 | B14: 의료 | C14: 간호주사 | D14: 이현숙 | E14: =VLOOKUP($D14,잔업시간!$D$3:'잔업시간'!$M$24,7,0) -> 36 | F14: =VLOOKUP($D14,잔업시간!$D$3:'잔업시간'!$M$24,8,0) -> 4 | G14: =VLOOKUP($D14,잔업시간!$D$3:'잔업시간'!$M$24,9,0) -> 2 | H14: =VLOOKUP($D14,잔업시간!$D$3:'잔업시간'!$M$24,10,0) -> 현업
A15: =ROW(A15)-ROW($A$5) -> 10 | B15: 의료 | C15: 의료기술주사 | D15: 유진수 | E15: =VLOOKUP($D15,잔업시간!$D$3:'잔업시간'!$M$24,7,0) -> 51 | F15: =VLOOKUP($D15,잔업시간!$D$3:'잔업시간'!$M$24,8,0) -> 5 | G15: =VLOOKUP($D15,잔업시간!$D$3:'잔업시간'!$M$24,9,0) -> 2 | H15: =VLOOKUP($D15,잔업시간!$D$3:'잔업시간'!$M$24,10,0) -> 현업
A16: =ROW(A16)-ROW($A$5) -> 11 | B16: 의료 | C16: 7급 | D16: 장민우 | E16: =VLOOKUP($D16,잔업시간!$D$3:'잔업시간'!$M$24,7,0) -> 7 | F16: =VLOOKUP($D16,잔업시간!$D$3:'잔업시간'!$M$24,8,0) -> 1 | G16: =VLOOKUP($D16,잔업시간!$D$3:'잔업시간'!$M$24,9,0) -> 0 | H16: =VLOOKUP($D16,잔업시간!$D$3:'잔업시간'!$M$24,10,0) -> 현업
A17: =ROW(A17)-ROW($A$5) -> 12 | B17: 의료 | C17: 7급 | D17: 송남철 | E17: =VLOOKUP($D17,잔업시간!$D$3:'잔업시간'!$M$24,7,0) -> 21 | F17: =VLOOKUP($D17,잔업시간!$D$3:'잔업시간'!$M$24,8,0) -> 3 | G17: =VLOOKUP($D17,잔업시간!$D$3:'잔업시간'!$M$24,9,0) -> 0 | H17: =VLOOKUP($D17,잔업시간!$D$3:'잔업시간'!$M$24,10,0) -> 현업
... A27: =ROW(A27)-ROW($A$5) -> 22 | B27: 의료 | C27: 8급 | D27: 이승현 | E27: =VLOOKUP($D27,잔업시간!$D$3:'잔업시간'!$M$24,7,0) -> 52 | F27: =VLOOKUP($D27,잔업시간!$D$3:'잔업시간'!$M$24,8,0) -> 4 | G27: =VLOOKUP($D27,잔업시간!$D$3:'잔업시간'!$M$24,9,0) -> 1 | H27: =VLOOKUP($D27,잔업시간!$D$3:'잔업시간'!$M$24,10,0) -> 현업
C29: 구 분 | D29: 총 원 (명) | E29: 초과시간합계 (시간) | F29: 최고초과시간 (시간) | G29: 최저초과시간 (시간) | H29: 평균초과시간 (시간)
C30: 현 업 | D30: 17 | E30: =SUM(E11:E27) -> 580 | F30: =MAX(E11:E27) -> 52 | G30: =MIN(E11:E27) -> 0 | H30: =ROUND(E30/D30, 2) -> 34.12
C31: 비현업 | D31: 4 | E31: =SUM(E6:E10) -> 0 | F31: =MAX(E6:E10) -> 0 | G31: =MIN(E6:E10) -> 0 | H31: =ROUND(E31/D31, 2) -> 0
C32: 총계(시간) | D32: =SUM(D30:D31) -> 21 | E32: =SUM(E30:E31) -> 580 | F32: 총 평균 초과 시간(시간) | H32: =ROUND(E32/D32, 2) -> 27.62

Sheet 중식
B1: A조 | C1: B조
